Workbook

Sheet SAP Results
A1: Frame | B1: Station | C1: OutputCase | D1: CaseType | E1: P | F1: V2 | G1: V3 | H1: T | I1: M2 | J1: M3 | K1: FrameElem | L1: ElemStation
A2: 1 | B2: 0 | C2: EX | D2: LinStatic | E2: 18.694 | F2: 40.724 | G2: 0 | H2: 0 | I2: 0 | J2: 125.8599 | K2: 1-1 | L2: 0
A3: 1 | B3: 2.6 | C3: EX | D3: LinStatic | E3: 18.694 | F3: 40.724 | G3: 0 | H3: 0 | I3: 0 | J3: 19.9776 | K3: 1-1 | L3: 2.6
A4: 1 | B4: 5.2 | C4: EX | D4: LinStatic | E4: 18.694 | F4: 40.724 | G4: 0 | H4: 0 | I4: 0 | J4: -85.9048 | K4: 1-1 | L4: 5.2
A5: 1 | B5: 0 | C5: G-1 | D5: LinStatic | E5: -152.782 | F5: -33.565 | G5: 0 | H5: 0 | I5: 0 | J5: -49.6551 | K5: 1-1 | L5: 0
A6: 1 | B6: 2.6 | C6: G-1 | D6: LinStatic | E6: -152.782 | F6: -33.565 | G6: 0 | H6: 0 | I6: 0 | J6: 37.6136 | K6: 1-1 | L6: 2.6
A7: 1 | B7: 5.2 | C7: G-1 | D7: LinStatic | E7: -152.782 | F7: -33.565 | G7: 0 | H7: 0 | I7: 0 | J7: 124.8822 | K7: 1-1 | L7: 5.2
A8: 1 | B8: 0 | C8: G-2 | D8: LinStatic | E8: 10.213 | F8: 1.025 | G8: 0 | H8: 0 | I8: 0 | J8: -4.8253 | K8: 1-1 | L8: 0
A9: 1 | B9: 2.6 | C9: G-2 | D9: LinStatic | E9: 10.213 | F9: 1.025 | G9: 0 | H9: 0 | I9: 0 | J9: -7.4898 | K9: 1-1 | L9: 2.6
A10: 1 | B10: 5.2 | C10: G-2 | D10: LinStatic | E10: 10.213 | F10: 1.025 | G10: 0 | H10: 0 | I10: 0 | J10: -10.1543 | K10: 1-1 | L10: 5.2
A11: 1 | B11: 0 | C11: Q-1 | D11: LinStatic | E11: -77.08 | F11: -16.934 | G11: 0 | H11: 0 | I11: 0 | J11: -25.0516 | K11: 1-1 | L11: 0
A12: 1 | B12: 2.6 | C12: Q-1 | D12: LinStatic | E12: -77.08 | F12: -16.934 | G12: 0 | H12: 0 | I12: 0 | J12: 18.9765 | K12: 1-1 | L12: 2.6
A13: 1 | B13: 5.2 | C13: Q-1 | D13: LinStatic | E13: -77.08 | F13: -16.934 | G13: 0 | H13: 0 | I13: 0 | J13: 63.0046 | K13: 1-1 | L13: 5.2
... A136: 5 | B136: 8.05 | C136: Q-2 | D136: LinStatic | E136: 0 | F136: 77.08 | G136: 0 | H136: 0 | I136: 0 | J136: -63.0046 | K136: 5-1 | L136: 8.05

Sheet G-1
A1: ='SAP Results'!A1 -> Frame | B1: ='SAP Results'!B1 -> Station | C1: ='SAP Results'!C1 -> OutputCase | D1: ='SAP Results'!D1 -> CaseType | E1: ='SAP Results'!E1 -> P | F1: ='SAP Results'!F1 -> V2 | G1: ='SAP Results'!G1 -> V3 | H1: ='SAP Results'!H1 -> T | ... L1: ='SAP Results'!L1 -> ElemStation
A2: ='SAP Results'!A2 -> 1 | B2: ='SAP Results'!B2 -> 0 | C2: ='SAP Results'!C2 -> EX | D2: ='SAP Results'!D2 -> LinStatic | E2: ='SAP Results'!E2 -> 18.694 | F2: ='SAP Results'!F2 -> 40.724 | G2: ='SAP Results'!G2 -> 0 | H2: ='SAP Results'!H2 -> 0 | ... L2: ='SAP Results'!L2 -> 0
A3: ='SAP Results'!A3 -> 1 | B3: ='SAP Results'!B3 -> 2.6 | C3: ='SAP Results'!C3 -> EX | D3: ='SAP Results'!D3 -> LinStatic | E3: ='SAP Results'!E3 -> 18.694 | F3: ='SAP Results'!F3 -> 40.724 | G3: ='SAP Results'!G3 -> 0 | H3: ='SAP Results'!H3 -> 0 | ... L3: ='SAP Results'!L3 -> 2.6
A4: ='SAP Results'!A4 -> 1 | B4: ='SAP Results'!B4 -> 5.2 | C4: ='SAP Results'!C4 -> EX | D4: ='SAP Results'!D4 -> LinStatic | E4: ='SAP Results'!E4 -> 18.694 | F4: ='SAP Results'!F4 -> 40.724 | G4: ='SAP Results'!G4 -> 0 | H4: ='SAP Results'!H4 -> 0 | ... L4: ='SAP Results'!L4 -> 5.2
A5: ='SAP Results'!A5 -> 1 | B5: ='SAP Results'!B5 -> 0 | C5: ='SAP Results'!C5 -> G-1 | D5: ='SAP Results'!D5 -> LinStatic | E5: ='SAP Results'!E5 -> -152.782 | F5: ='SAP Results'!F5 -> -33.565 | G5: ='SAP Results'!G5 -> 0 | H5: ='SAP Results'!H5 -> 0 | ... L5: ='SAP Results'!L5 -> 0
A6: ='SAP Results'!A6 -> 1 | B6: ='SAP Results'!B6 -> 2.6 | C6: ='SAP Results'!C6 -> G-1 | D6: ='SAP Results'!D6 -> LinStatic | E6: ='SAP Results'!E6 -> -152.782 | F6: ='SAP Results'!F6 -> -33.565 | G6: ='SAP Results'!G6 -> 0 | H6: ='SAP Results'!H6 -> 0 | ... L6: ='SAP Results'!L6 -> 2.6
A7: ='SAP Results'!A7 -> 1 | B7: ='SAP Results'!B7 -> 5.2 | C7: ='SAP Results'!C7 -> G-1 | D7: ='SAP Results'!D7 -> LinStatic | E7: ='SAP Results'!E7 -> -152.782 | F7: ='SAP Results'!F7 -> -33.565 | G7: ='SAP Results'!G7 -> 0 | H7: ='SAP Results'!H7 -> 0 | ... L7: ='SAP Results'!L7 -> 5.2
A8: ='SAP Results'!A8 -> 1 | B8: ='SAP Results'!B8 -> 0 | C8: ='SAP Results'!C8 -> G-2 | D8: ='SAP Results'!D8 -> LinStatic | E8: ='SAP Results'!E8 -> 10.213 | F8: ='SAP Results'!F8 -> 1.025 | G8: ='SAP Results'!G8 -> 0 | H8: ='SAP Results'!H8 -> 0 | ... L8: ='SAP Results'!L8 -> 0
A9: ='SAP Results'!A9 -> 1 | B9: ='SAP Results'!B9 -> 2.6 | C9: ='SAP Results'!C9 -> G-2 | D9: ='SAP Results'!D9 -> LinStatic | E9: ='SAP Results'!E9 -> 10.213 | F9: ='SAP Results'!F9 -> 1.025 | G9: ='SAP Results'!G9 -> 0 | H9: ='SAP Results'!H9 -> 0 | ... L9: ='SAP Results'!L9 -> 2.6
A10: ='SAP Results'!A10 -> 1 | B10: ='SAP Results'!B10 -> 5.2 | C10: ='SAP Results'!C10 -> G-2 | D10: ='SAP Results'!D10 -> LinStatic | E10: ='SAP Results'!E10 -> 10.213 | F10: ='SAP Results'!F10 -> 1.025 | G10: ='SAP Results'!G10 -> 0 | H10: ='SAP Results'!H10 -> 0 | ... L10: ='SAP Results'!L10 -> 5.2
A11: ='SAP Results'!A11 -> 1 | B11: ='SAP Results'!B11 -> 0 | C11: ='SAP Results'!C11 -> Q-1 | D11: ='SAP Results'!D11 -> LinStatic | E11: ='SAP Results'!E11 -> -77.08 | F11: ='SAP Results'!F11 -> -16.934 | G11: ='SAP Results'!G11 -> 0 | H11: ='SAP Results'!H11 -> 0 | ... L11: ='SAP Results'!L11 -> 0
A12: ='SAP Results'!A12 -> 1 | B12: ='SAP Results'!B12 -> 2.6 | C12: ='SAP Results'!C12 -> Q-1 | D12: ='SAP Results'!D12 -> LinStatic | E12: ='SAP Results'!E12 -> -77.08 | F12: ='SAP Results'!F12 -> -16.934 | G12: ='SAP Results'!G12 -> 0 | H12: ='SAP Results'!H12 -> 0 | ... L12: ='SAP Results'!L12 -> 2.6
... A136: ='SAP Results'!A136 -> 5 | B136: ='SAP Results'!B136 -> 8.05 | C136: ='SAP Results'!C136 -> Q-2 | D136: ='SAP Results'!D136 -> LinStatic | E136: ='SAP Results'!E136 -> 0 | F136: ='SAP Results'!F136 -> 77.08 | G136: ='SAP Results'!G136 -> 0 | H136: ='SAP Results'!H136 -> 0 | ... L136: ='SAP Results'!L136 -> 8.05

Sheet G-2
A1: ='SAP Results'!A1 -> Frame | B1: ='SAP Results'!B1 -> Station | C1: ='SAP Results'!C1 -> OutputCase | D1: ='SAP Results'!D1 -> CaseType | E1: ='SAP Results'!E1 -> P | F1: ='SAP Results'!F1 -> V2 | G1: ='SAP Results'!G1 -> V3 | H1: ='SAP Results'!H1 -> T | ... L1: ='SAP Results'!L1 -> ElemStation
A2: ='SAP Results'!A2 -> 1 | B2: ='SAP Results'!B2 -> 0 | C2: ='SAP Results'!C2 -> EX | D2: ='SAP Results'!D2 -> LinStatic | E2: ='SAP Results'!E2 -> 18.694 | F2: ='SAP Results'!F2 -> 40.724 | G2: ='SAP Results'!G2 -> 0 | H2: ='SAP Results'!H2 -> 0 | ... L2: ='SAP Results'!L2 -> 0
A3: ='SAP Results'!A3 -> 1 | B3: ='SAP Results'!B3 -> 2.6 | C3: ='SAP Results'!C3 -> EX | D3: ='SAP Results'!D3 -> LinStatic | E3: ='SAP Results'!E3 -> 18.694 | F3: ='SAP Results'!F3 -> 40.724 | G3: ='SAP Results'!G3 -> 0 | H3: ='SAP Results'!H3 -> 0 | ... L3: ='SAP Results'!L3 -> 2.6
A4: ='SAP Results'!A4 -> 1 | B4: ='SAP Results'!B4 -> 5.2 | C4: ='SAP Results'!C4 -> EX | D4: ='SAP Results'!D4 -> LinStatic | E4: ='SAP Results'!E4 -> 18.694 | F4: ='SAP Results'!F4 -> 40.724 | G4: ='SAP Results'!G4 -> 0 | H4: ='SAP Results'!H4 -> 0 | ... L4: ='SAP Results'!L4 -> 5.2
A5: ='SAP Results'!A5 -> 1 | B5: ='SAP Results'!B5 -> 0 | C5: ='SAP Results'!C5 -> G-1 | D5: ='SAP Results'!D5 -> LinStatic | E5: ='SAP Results'!E5 -> -152.782 | F5: ='SAP Results'!F5 -> -33.565 | G5: ='SAP Results'!G5 -> 0 | H5: ='SAP Results'!H5 -> 0 | ... L5: ='SAP Results'!L5 -> 0
A6: ='SAP Results'!A6 -> 1 | B6: ='SAP Results'!B6 -> 2.6 | C6: ='SAP Results'!C6 -> G-1 | D6: ='SAP Results'!D6 -> LinStatic | E6: ='SAP Results'!E6 -> -152.782 | F6: ='SAP Results'!F6 -> -33.565 | G6: ='SAP Results'!G6 -> 0 | H6: ='SAP Results'!H6 -> 0 | ... L6: ='SAP Results'!L6 -> 2.6
A7: ='SAP Results'!A7 -> 1 | B7: ='SAP Results'!B7 -> 5.2 | C7: ='SAP Results'!C7 -> G-1 | D7: ='SAP Results'!D7 -> LinStatic | E7: ='SAP Results'!E7 -> -152.782 | F7: ='SAP Results'!F7 -> -33.565 | G7: ='SAP Results'!G7 -> 0 | H7: ='SAP Results'!H7 -> 0 | ... L7: ='SAP Results'!L7 -> 5.2
A8: ='SAP Results'!A8 -> 1 | B8: ='SAP Results'!B8 -> 0 | C8: ='SAP Results'!C8 -> G-2 | D8: ='SAP Results'!D8 -> LinStatic | E8: ='SAP Results'!E8 -> 10.213 | F8: ='SAP Results'!F8 -> 1.025 | G8: ='SAP Results'!G8 -> 0 | H8: ='SAP Results'!H8 -> 0 | ... L8: ='SAP Results'!L8 -> 0
A9: ='SAP Results'!A9 -> 1 | B9: ='SAP Results'!B9 -> 2.6 | C9: ='SAP Results'!C9 -> G-2 | D9: ='SAP Results'!D9 -> LinStatic | E9: ='SAP Results'!E9 -> 10.213 | F9: ='SAP Results'!F9 -> 1.025 | G9: ='SAP Results'!G9 -> 0 | H9: ='SAP Results'!H9 -> 0 | ... L9: ='SAP Results'!L9 -> 2.6
A10: ='SAP Results'!A10 -> 1 | B10: ='SAP Results'!B10 -> 5.2 | C10: ='SAP Results'!C10 -> G-2 | D10: ='SAP Results'!D10 -> LinStatic | E10: ='SAP Results'!E10 -> 10.213 | F10: ='SAP Results'!F10 -> 1.025 | G10: ='SAP Results'!G10 -> 0 | H10: ='SAP Results'!H10 -> 0 | ... L10: ='SAP Results'!L10 -> 5.2
A11: ='SAP Results'!A11 -> 1 | B11: ='SAP Results'!B11 -> 0 | C11: ='SAP Results'!C11 -> Q-1 | D11: ='SAP Results'!D11 -> LinStatic | E11: ='SAP Results'!E11 -> -77.08 | F11: ='SAP Results'!F11 -> -16.934 | G11: ='SAP Results'!G11 -> 0 | H11: ='SAP Results'!H11 -> 0 | ... L11: ='SAP Results'!L11 -> 0
A12: ='SAP Results'!A12 -> 1 | B12: ='SAP Results'!B12 -> 2.6 | C12: ='SAP Results'!C12 -> Q-1 | D12: ='SAP Results'!D12 -> LinStatic | E12: ='SAP Results'!E12 -> -77.08 | F12: ='SAP Results'!F12 -> -16.934 | G12: ='SAP Results'!G12 -> 0 | H12: ='SAP Results'!H12 -> 0 | ... L12: ='SAP Results'!L12 -> 2.6
... A136: ='SAP Results'!A136 -> 5 | B136: ='SAP Results'!B136 -> 8.05 | C136: ='SAP Results'!C136 -> Q-2 | D136: ='SAP Results'!D136 -> LinStatic | E136: ='SAP Results'!E136 -> 0 | F136: ='SAP Results'!F136 -> 77.08 | G136: ='SAP Results'!G136 -> 0 | H136: ='SAP Results'!H136 -> 0 | ... L136: ='SAP Results'!L136 -> 8.05

Sheet Q-1
A1: ='SAP Results'!A1 -> Frame | B1: ='SAP Results'!B1 -> Station | C1: ='SAP Results'!C1 -> OutputCase | D1: ='SAP Results'!D1 -> CaseType | E1: ='SAP Results'!E1 -> P | F1: ='SAP Results'!F1 -> V2 | G1: ='SAP Results'!G1 -> V3 | H1: ='SAP Results'!H1 -> T | ... L1: ='SAP Results'!L1 -> ElemStation
A2: ='SAP Results'!A2 -> 1 | B2: ='SAP Results'!B2 -> 0 | C2: ='SAP Results'!C2 -> EX | D2: ='SAP Results'!D2 -> LinStatic | E2: ='SAP Results'!E2 -> 18.694 | F2: ='SAP Results'!F2 -> 40.724 | G2: ='SAP Results'!G2 -> 0 | H2: ='SAP Results'!H2 -> 0 | ... L2: ='SAP Results'!L2 -> 0
A3: ='SAP Results'!A3 -> 1 | B3: ='SAP Results'!B3 -> 2.6 | C3: ='SAP Results'!C3 -> EX | D3: ='SAP Results'!D3 -> LinStatic | E3: ='SAP Results'!E3 -> 18.694 | F3: ='SAP Results'!F3 -> 40.724 | G3: ='SAP Results'!G3 -> 0 | H3: ='SAP Results'!H3 -> 0 | ... L3: ='SAP Results'!L3 -> 2.6
A4: ='SAP Results'!A4 -> 1 | B4: ='SAP Results'!B4 -> 5.2 | C4: ='SAP Results'!C4 -> EX | D4: ='SAP Results'!D4 -> LinStatic | E4: ='SAP Results'!E4 -> 18.694 | F4: ='SAP Results'!F4 -> 40.724 | G4: ='SAP Results'!G4 -> 0 | H4: ='SAP Results'!H4 -> 0 | ... L4: ='SAP Results'!L4 -> 5.2
A5: ='SAP Results'!A5 -> 1 | B5: ='SAP Results'!B5 -> 0 | C5: ='SAP Results'!C5 -> G-1 | D5: ='SAP Results'!D5 -> LinStatic | E5: ='SAP Results'!E5 -> -152.782 | F5: ='SAP Results'!F5 -> -33.565 | G5: ='SAP Results'!G5 -> 0 | H5: ='SAP Results'!H5 -> 0 | ... L5: ='SAP Results'!L5 -> 0
A6: ='SAP Results'!A6 -> 1 | B6: ='SAP Results'!B6 -> 2.6 | C6: ='SAP Results'!C6 -> G-1 | D6: ='SAP Results'!D6 -> LinStatic | E6: ='SAP Results'!E6 -> -152.782 | F6: ='SAP Results'!F6 -> -33.565 | G6: ='SAP Results'!G6 -> 0 | H6: ='SAP Results'!H6 -> 0 | ... L6: ='SAP Results'!L6 -> 2.6
A7: ='SAP Results'!A7 -> 1 | B7: ='SAP Results'!B7 -> 5.2 | C7: ='SAP Results'!C7 -> G-1 | D7: ='SAP Results'!D7 -> LinStatic | E7: ='SAP Results'!E7 -> -152.782 | F7: ='SAP Results'!F7 -> -33.565 | G7: ='SAP Results'!G7 -> 0 | H7: ='SAP Results'!H7 -> 0 | ... L7: ='SAP Results'!L7 -> 5.2
A8: ='SAP Results'!A8 -> 1 | B8: ='SAP Results'!B8 -> 0 | C8: ='SAP Results'!C8 -> G-2 | D8: ='SAP Results'!D8 -> LinStatic | E8: ='SAP Results'!E8 -> 10.213 | F8: ='SAP Results'!F8 -> 1.025 | G8: ='SAP Results'!G8 -> 0 | H8: ='SAP Results'!H8 -> 0 | ... L8: ='SAP Results'!L8 -> 0
A9: ='SAP Results'!A9 -> 1 | B9: ='SAP Results'!B9 -> 2.6 | C9: ='SAP Results'!C9 -> G-2 | D9: ='SAP Results'!D9 -> LinStatic | E9: ='SAP Results'!E9 -> 10.213 | F9: ='SAP Results'!F9 -> 1.025 | G9: ='SAP Results'!G9 -> 0 | H9: ='SAP Results'!H9 -> 0 | ... L9: ='SAP Results'!L9 -> 2.6
A10: ='SAP Results'!A10 -> 1 | B10: ='SAP Results'!B10 -> 5.2 | C10: ='SAP Results'!C10 -> G-2 | D10: ='SAP Results'!D10 -> LinStatic | E10: ='SAP Results'!E10 -> 10.213 | F10: ='SAP Results'!F10 -> 1.025 | G10: ='SAP Results'!G10 -> 0 | H10: ='SAP Results'!H10 -> 0 | ... L10: ='SAP Results'!L10 -> 5.2
A11: ='SAP Results'!A11 -> 1 | B11: ='SAP Results'!B11 -> 0 | C11: ='SAP Results'!C11 -> Q-1 | D11: ='SAP Results'!D11 -> LinStatic | E11: ='SAP Results'!E11 -> -77.08 | F11: ='SAP Results'!F11 -> -16.934 | G11: ='SAP Results'!G11 -> 0 | H11: ='SAP Results'!H11 -> 0 | ... L11: ='SAP Results'!L11 -> 0
A12: ='SAP Results'!A12 -> 1 | B12: ='SAP Results'!B12 -> 2.6 | C12: ='SAP Results'!C12 -> Q-1 | D12: ='SAP Results'!D12 -> LinStatic | E12: ='SAP Results'!E12 -> -77.08 | F12: ='SAP Results'!F12 -> -16.934 | G12: ='SAP Results'!G12 -> 0 | H12: ='SAP Results'!H12 -> 0 | ... L12: ='SAP Results'!L12 -> 2.6
... A136: ='SAP Results'!A136 -> 5 | B136: ='SAP Results'!B136 -> 8.05 | C136: ='SAP Results'!C136 -> Q-2 | D136: ='SAP Results'!D136 -> LinStatic | E136: ='SAP Results'!E136 -> 0 | F136: ='SAP Results'!F136 -> 77.08 | G136: ='SAP Results'!G136 -> 0 | H136: ='SAP Results'!H136 -> 0 | ... L136: ='SAP Results'!L136 -> 8.05

Sheet Q-2
A1: ='SAP Results'!A1 -> Frame | B1: ='SAP Results'!B1 -> Station | C1: ='SAP Results'!C1 -> OutputCase | D1: ='SAP Results'!D1 -> CaseType | E1: ='SAP Results'!E1 -> P | F1: ='SAP Results'!F1 -> V2 | G1: ='SAP Results'!G1 -> V3 | H1: ='SAP Results'!H1 -> T | ... L1: ='SAP Results'!L1 -> ElemStation
A2: ='SAP Results'!A2 -> 1 | B2: ='SAP Results'!B2 -> 0 | C2: ='SAP Results'!C2 -> EX | D2: ='SAP Results'!D2 -> LinStatic | E2: ='SAP Results'!E2 -> 18.694 | F2: ='SAP Results'!F2 -> 40.724 | G2: ='SAP Results'!G2 -> 0 | H2: ='SAP Results'!H2 -> 0 | ... L2: ='SAP Results'!L2 -> 0
A3: ='SAP Results'!A3 -> 1 | B3: ='SAP Results'!B3 -> 2.6 | C3: ='SAP Results'!C3 -> EX | D3: ='SAP Results'!D3 -> LinStatic | E3: ='SAP Results'!E3 -> 18.694 | F3: ='SAP Results'!F3 -> 40.724 | G3: ='SAP Results'!G3 -> 0 | H3: ='SAP Results'!H3 -> 0 | ... L3: ='SAP Results'!L3 -> 2.6
A4: ='SAP Results'!A4 -> 1 | B4: ='SAP Results'!B4 -> 5.2 | C4: ='SAP Results'!C4 -> EX | D4: ='SAP Results'!D4 -> LinStatic | E4: ='SAP Results'!E4 -> 18.694 | F4: ='SAP Results'!F4 -> 40.724 | G4: ='SAP Results'!G4 -> 0 | H4: ='SAP Results'!H4 -> 0 | ... L4: ='SAP Results'!L4 -> 5.2
A5: ='SAP Results'!A5 -> 1 | B5: ='SAP Results'!B5 -> 0 | C5: ='SAP Results'!C5 -> G-1 | D5: ='SAP Results'!D5 -> LinStatic | E5: ='SAP Results'!E5 -> -152.782 | F5: ='SAP Results'!F5 -> -33.565 | G5: ='SAP Results'!G5 -> 0 | H5: ='SAP Results'!H5 -> 0 | ... L5: ='SAP Results'!L5 -> 0
A6: ='SAP Results'!A6 -> 1 | B6: ='SAP Results'!B6 -> 2.6 | C6: ='SAP Results'!C6 -> G-1 | D6: ='SAP Results'!D6 -> LinStatic | E6: ='SAP Results'!E6 -> -152.782 | F6: ='SAP Results'!F6 -> -33.565 | G6: ='SAP Results'!G6 -> 0 | H6: ='SAP Results'!H6 -> 0 | ... L6: ='SAP Results'!L6 -> 2.6
A7: ='SAP Results'!A7 -> 1 | B7: ='SAP Results'!B7 -> 5.2 | C7: ='SAP Results'!C7 -> G-1 | D7: ='SAP Results'!D7 -> LinStatic | E7: ='SAP Results'!E7 -> -152.782 | F7: ='SAP Results'!F7 -> -33.565 | G7: ='SAP Results'!G7 -> 0 | H7: ='SAP Results'!H7 -> 0 | ... L7: ='SAP Results'!L7 -> 5.2
A8: ='SAP Results'!A8 -> 1 | B8: ='SAP Results'!B8 -> 0 | C8: ='SAP Results'!C8 -> G-2 | D8: ='SAP Results'!D8 -> LinStatic | E8: ='SAP Results'!E8 -> 10.213 | F8: ='SAP Results'!F8 -> 1.025 | G8: ='SAP Results'!G8 -> 0 | H8: ='SAP Results'!H8 -> 0 | ... L8: ='SAP Results'!L8 -> 0
A9: ='SAP Results'!A9 -> 1 | B9: ='SAP Results'!B9 -> 2.6 | C9: ='SAP Results'!C9 -> G-2 | D9: ='SAP Results'!D9 -> LinStatic | E9: ='SAP Results'!E9 -> 10.213 | F9: ='SAP Results'!F9 -> 1.025 | G9: ='SAP Results'!G9 -> 0 | H9: ='SAP Results'!H9 -> 0 | ... L9: ='SAP Results'!L9 -> 2.6
A10: ='SAP Results'!A10 -> 1 | B10: ='SAP Results'!B10 -> 5.2 | C10: ='SAP Results'!C10 -> G-2 | D10: ='SAP Results'!D10 -> LinStatic | E10: ='SAP Results'!E10 -> 10.213 | F10: ='SAP Results'!F10 -> 1.025 | G10: ='SAP Results'!G10 -> 0 | H10: ='SAP Results'!H10 -> 0 | ... L10: ='SAP Results'!L10 -> 5.2
A11: ='SAP Results'!A11 -> 1 | B11: ='SAP Results'!B11 -> 0 | C11: ='SAP Results'!C11 -> Q-1 | D11: ='SAP Results'!D11 -> LinStatic | E11: ='SAP Results'!E11 -> -77.08 | F11: ='SAP Results'!F11 -> -16.934 | G11: ='SAP Results'!G11 -> 0 | H11: ='SAP Results'!H11 -> 0 | ... L11: ='SAP Results'!L11 -> 0
A12: ='SAP Results'!A12 -> 1 | B12: ='SAP Results'!B12 -> 2.6 | C12: ='SAP Results'!C12 -> Q-1 | D12: ='SAP Results'!D12 -> LinStatic | E12: ='SAP Results'!E12 -> -77.08 | F12: ='SAP Results'!F12 -> -16.934 | G12: ='SAP Results'!G12 -> 0 | H12: ='SAP Results'!H12 -> 0 | ... L12: ='SAP Results'!L12 -> 2.6
... A136: ='SAP Results'!A136 -> 5 | B136: ='SAP Results'!B136 -> 8.05 | C136: ='SAP Results'!C136 -> Q-2 | D136: ='SAP Results'!D136 -> LinStatic | E136: ='SAP Results'!E136 -> 0 | F136: ='SAP Results'!F136 -> 77.08 | G136: ='SAP Results'!G136 -> 0 | H136: ='SAP Results'!H136 -> 0 | ... L136: ='SAP Results'!L136 -> 8.05

Sheet EX
A1: ='SAP Results'!A1 -> Frame | B1: ='SAP Results'!B1 -> Station | C1: ='SAP Results'!C1 -> OutputCase | D1: ='SAP Results'!D1 -> CaseType | E1: ='SAP Results'!E1 -> P | F1: ='SAP Results'!F1 -> V2 | G1: ='SAP Results'!G1 -> V3 | H1: ='SAP Results'!H1 -> T | ... L1: ='SAP Results'!L1 -> ElemStation
A2: ='SAP Results'!A2 -> 1 | B2: ='SAP Results'!B2 -> 0 | C2: ='SAP Results'!C2 -> EX | D2: ='SAP Results'!D2 -> LinStatic | E2: ='SAP Results'!E2 -> 18.694 | F2: ='SAP Results'!F2 -> 40.724 | G2: ='SAP Results'!G2 -> 0 | H2: ='SAP Results'!H2 -> 0 | ... L2: ='SAP Results'!L2 -> 0
A3: ='SAP Results'!A3 -> 1 | B3: ='SAP Results'!B3 -> 2.6 | C3: ='SAP Results'!C3 -> EX | D3: ='SAP Results'!D3 -> LinStatic | E3: ='SAP Results'!E3 -> 18.694 | F3: ='SAP Results'!F3 -> 40.724 | G3: ='SAP Results'!G3 -> 0 | H3: ='SAP Results'!H3 -> 0 | ... L3: ='SAP Results'!L3 -> 2.6
A4: ='SAP Results'!A4 -> 1 | B4: ='SAP Results'!B4 -> 5.2 | C4: ='SAP Results'!C4 -> EX | D4: ='SAP Results'!D4 -> LinStatic | E4: ='SAP Results'!E4 -> 18.694 | F4: ='SAP Results'!F4 -> 40.724 | G4: ='SAP Results'!G4 -> 0 | H4: ='SAP Results'!H4 -> 0 | ... L4: ='SAP Results'!L4 -> 5.2
A5: ='SAP Results'!A5 -> 1 | B5: ='SAP Results'!B5 -> 0 | C5: ='SAP Results'!C5 -> G-1 | D5: ='SAP Results'!D5 -> LinStatic | E5: ='SAP Results'!E5 -> -152.782 | F5: ='SAP Results'!F5 -> -33.565 | G5: ='SAP Results'!G5 -> 0 | H5: ='SAP Results'!H5 -> 0 | ... L5: ='SAP Results'!L5 -> 0
A6: ='SAP Results'!A6 -> 1 | B6: ='SAP Results'!B6 -> 2.6 | C6: ='SAP Results'!C6 -> G-1 | D6: ='SAP Results'!D6 -> LinStatic | E6: ='SAP Results'!E6 -> -152.782 | F6: ='SAP Results'!F6 -> -33.565 | G6: ='SAP Results'!G6 -> 0 | H6: ='SAP Results'!H6 -> 0 | ... L6: ='SAP Results'!L6 -> 2.6
A7: ='SAP Results'!A7 -> 1 | B7: ='SAP Results'!B7 -> 5.2 | C7: ='SAP Results'!C7 -> G-1 | D7: ='SAP Results'!D7 -> LinStatic | E7: ='SAP Results'!E7 -> -152.782 | F7: ='SAP Results'!F7 -> -33.565 | G7: ='SAP Results'!G7 -> 0 | H7: ='SAP Results'!H7 -> 0 | ... L7: ='SAP Results'!L7 -> 5.2
A8: ='SAP Results'!A8 -> 1 | B8: ='SAP Results'!B8 -> 0 | C8: ='SAP Results'!C8 -> G-2 | D8: ='SAP Results'!D8 -> LinStatic | E8: ='SAP Results'!E8 -> 10.213 | F8: ='SAP Results'!F8 -> 1.025 | G8: ='SAP Results'!G8 -> 0 | H8: ='SAP Results'!H8 -> 0 | ... L8: ='SAP Results'!L8 -> 0
A9: ='SAP Results'!A9 -> 1 | B9: ='SAP Results'!B9 -> 2.6 | C9: ='SAP Results'!C9 -> G-2 | D9: ='SAP Results'!D9 -> LinStatic | E9: ='SAP Results'!E9 -> 10.213 | F9: ='SAP Results'!F9 -> 1.025 | G9: ='SAP Results'!G9 -> 0 | H9: ='SAP Results'!H9 -> 0 | ... L9: ='SAP Results'!L9 -> 2.6
A10: ='SAP Results'!A10 -> 1 | B10: ='SAP Results'!B10 -> 5.2 | C10: ='SAP Results'!C10 -> G-2 | D10: ='SAP Results'!D10 -> LinStatic | E10: ='SAP Results'!E10 -> 10.213 | F10: ='SAP Results'!F10 -> 1.025 | G10: ='SAP Results'!G10 -> 0 | H10: ='SAP Results'!H10 -> 0 | ... L10: ='SAP Results'!L10 -> 5.2
A11: ='SAP Results'!A11 -> 1 | B11: ='SAP Results'!B11 -> 0 | C11: ='SAP Results'!C11 -> Q-1 | D11: ='SAP Results'!D11 -> LinStatic | E11: ='SAP Results'!E11 -> -77.08 | F11: ='SAP Results'!F11 -> -16.934 | G11: ='SAP Results'!G11 -> 0 | H11: ='SAP Results'!H11 -> 0 | ... L11: ='SAP Results'!L11 -> 0
A12: ='SAP Results'!A12 -> 1 | B12: ='SAP Results'!B12 -> 2.6 | C12: ='SAP Results'!C12 -> Q-1 | D12: ='SAP Results'!D12 -> LinStatic | E12: ='SAP Results'!E12 -> -77.08 | F12: ='SAP Results'!F12 -> -16.934 | G12: ='SAP Results'!G12 -> 0 | H12: ='SAP Results'!H12 -> 0 | ... L12: ='SAP Results'!L12 -> 2.6
... A136: ='SAP Results'!A136 -> 5 | B136: ='SAP Results'!B136 -> 8.05 | C136: ='SAP Results'!C136 -> Q-2 | D136: ='SAP Results'!D136 -> LinStatic | E136: ='SAP Results'!E136 -> 0 | F136: ='SAP Results'!F136 -> 77.08 | G136: ='SAP Results'!G136 -> 0 | H136: ='SAP Results'!H136 -> 0 | ... L136: ='SAP Results'!L136 -> 8.05

Sheet Δ-Δ
A1: Frame | B1: Station | C1: P | D1: V2 | E1: V3 | F1: T | G1: M2 | H1: M3
A2: 1 | B2: 0 | C2: =1.35*('G-1'!E5+'G-2'!E8)+1.5*('Q-1'!E11+'Q-2'!E14) -> -300.35865 | D2: =1.35*('G-1'!F5+'G-2'!F8)+1.5*('Q-1'!F11+'Q-2'!F14) -> -68.5545 | E2: =1.35*('G-1'!G5+'G-2'!G8)+1.5*('Q-1'!G11+'Q-2'!G14) -> 0 | F2: =1.35*('G-1'!H5+'G-2'!H8)+1.5*('Q-1'!H11+'Q-2'!H14) -> 0 | G2: =1.35*('G-1'!I5+'G-2'!I8)+1.5*('Q-1'!I11+'Q-2'!I14) -> 0 | H2: =1.35*('G-1'!J5+'G-2'!J8)+1.5*('Q-1'!J11+'Q-2'!J14) -> -114.77754
A3: 1 | B3: 3.25 | C3: =1.35*('G-1'!E6+'G-2'!E9)+1.5*('Q-1'!E12+'Q-2'!E15) -> -300.35865 | D3: =1.35*('G-1'!F6+'G-2'!F9)+1.5*('Q-1'!F12+'Q-2'!F15) -> -68.5545 | E3: =1.35*('G-1'!G6+'G-2'!G9)+1.5*('Q-1'!G12+'Q-2'!G15) -> 0 | F3: =1.35*('G-1'!H6+'G-2'!H9)+1.5*('Q-1'!H12+'Q-2'!H15) -> 0 | G3: =1.35*('G-1'!I6+'G-2'!I9)+1.5*('Q-1'!I12+'Q-2'!I15) -> 0 | H3: =1.35*('G-1'!J6+'G-2'!J9)+1.5*('Q-1'!J12+'Q-2'!J15) -> 63.46383
A4: 1 | B4: 6.5 | C4: =1.35*('G-1'!E7+'G-2'!E10)+1.5*('Q-1'!E13+'Q-2'!E16) -> -300.35865 | D4: =1.35*('G-1'!F7+'G-2'!F10)+1.5*('Q-1'!F13+'Q-2'!F16) -> -68.5545 | E4: =1.35*('G-1'!G7+'G-2'!G10)+1.5*('Q-1'!G13+'Q-2'!G16) -> 0 | F4: =1.35*('G-1'!H7+'G-2'!H10)+1.5*('Q-1'!H13+'Q-2'!H16) -> 0 | G4: =1.35*('G-1'!I7+'G-2'!I10)+1.5*('Q-1'!I13+'Q-2'!I16) -> 0 | H4: =1.35*('G-1'!J7+'G-2'!J10)+1.5*('Q-1'!J13+'Q-2'!J16) -> 241.70507
A5: 2 | B5: 0 | C5: =1.35*('G-1'!E20+'G-2'!E23)+1.5*('Q-1'!E26+'Q-2'!E29) -> -752.3112 | D5: =1.35*('G-1'!F20+'G-2'!F23)+1.5*('Q-1'!F26+'Q-2'!F29) -> 0 | E5: =1.35*('G-1'!G20+'G-2'!G23)+1.5*('Q-1'!G26+'Q-2'!G29) -> 0 | F5: =1.35*('G-1'!H20+'G-2'!H23)+1.5*('Q-1'!H26+'Q-2'!H29) -> 0 | G5: =1.35*('G-1'!I20+'G-2'!I23)+1.5*('Q-1'!I26+'Q-2'!I29) -> 0 | H5: =1.35*('G-1'!J20+'G-2'!J23)+1.5*('Q-1'!J26+'Q-2'!J29) -> 0
A6: 2 | B6: 3.25 | C6: =1.35*('G-1'!E21+'G-2'!E24)+1.5*('Q-1'!E27+'Q-2'!E30) -> -752.3112 | D6: =1.35*('G-1'!F21+'G-2'!F24)+1.5*('Q-1'!F27+'Q-2'!F30) -> 0 | E6: =1.35*('G-1'!G21+'G-2'!G24)+1.5*('Q-1'!G27+'Q-2'!G30) -> 0 | F6: =1.35*('G-1'!H21+'G-2'!H24)+1.5*('Q-1'!H27+'Q-2'!H30) -> 0 | G6: =1.35*('G-1'!I21+'G-2'!I24)+1.5*('Q-1'!I27+'Q-2'!I30) -> 0 | H6: =1.35*('G-1'!J21+'G-2'!J24)+1.5*('Q-1'!J27+'Q-2'!J30) -> 0
A7: 2 | B7: 6.5 | C7: =1.35*('G-1'!E22+'G-2'!E25)+1.5*('Q-1'!E28+'Q-2'!E31) -> -752.3112 | D7: =1.35*('G-1'!F22+'G-2'!F25)+1.5*('Q-1'!F28+'Q-2'!F31) -> 0 | E7: =1.35*('G-1'!G22+'G-2'!G25)+1.5*('Q-1'!G28+'Q-2'!G31) -> 0 | F7: =1.35*('G-1'!H22+'G-2'!H25)+1.5*('Q-1'!H28+'Q-2'!H31) -> 0 | G7: =1.35*('G-1'!I22+'G-2'!I25)+1.5*('Q-1'!I28+'Q-2'!I31) -> 0 | H7: =1.35*('G-1'!J22+'G-2'!J25)+1.5*('Q-1'!J28+'Q-2'!J31) -> 0
A8: 3 | B8: 0 | C8: =1.35*('G-1'!E35+'G-2'!E38)+1.5*('Q-1'!E41+'Q-2'!E44) -> -300.35865 | D8: =1.35*('G-1'!F35+'G-2'!F38)+1.5*('Q-1'!F41+'Q-2'!F44) -> 68.5545 | E8: =1.35*('G-1'!G35+'G-2'!G38)+1.5*('Q-1'!G41+'Q-2'!G44) -> 0 | F8: =1.35*('G-1'!H35+'G-2'!H38)+1.5*('Q-1'!H41+'Q-2'!H44) -> 0 | G8: =1.35*('G-1'!I35+'G-2'!I38)+1.5*('Q-1'!I41+'Q-2'!I44) -> 0 | H8: =1.35*('G-1'!J35+'G-2'!J38)+1.5*('Q-1'!J41+'Q-2'!J44) -> 114.77754
A9: 3 | B9: 3.25 | C9: =1.35*('G-1'!E36+'G-2'!E39)+1.5*('Q-1'!E42+'Q-2'!E45) -> -300.35865 | D9: =1.35*('G-1'!F36+'G-2'!F39)+1.5*('Q-1'!F42+'Q-2'!F45) -> 68.5545 | E9: =1.35*('G-1'!G36+'G-2'!G39)+1.5*('Q-1'!G42+'Q-2'!G45) -> 0 | F9: =1.35*('G-1'!H36+'G-2'!H39)+1.5*('Q-1'!H42+'Q-2'!H45) -> 0 | G9: =1.35*('G-1'!I36+'G-2'!I39)+1.5*('Q-1'!I42+'Q-2'!I45) -> 0 | H9: =1.35*('G-1'!J36+'G-2'!J39)+1.5*('Q-1'!J42+'Q-2'!J45) -> -63.46383
A10: 3 | B10: 6.5 | C10: =1.35*('G-1'!E37+'G-2'!E40)+1.5*('Q-1'!E43+'Q-2'!E46) -> -300.35865 | D10: =1.35*('G-1'!F37+'G-2'!F40)+1.5*('Q-1'!F43+'Q-2'!F46) -> 68.5545 | E10: =1.35*('G-1'!G37+'G-2'!G40)+1.5*('Q-1'!G43+'Q-2'!G46) -> 0 | F10: =1.35*('G-1'!H37+'G-2'!H40)+1.5*('Q-1'!H43+'Q-2'!H46) -> 0 | G10: =1.35*('G-1'!I37+'G-2'!I40)+1.5*('Q-1'!I43+'Q-2'!I46) -> 0 | H10: =1.35*('G-1'!J37+'G-2'!J40)+1.5*('Q-1'!J43+'Q-2'!J46) -> -241.70507
A11: 4 | B11: 0 | C11: =1.35*('G-1'!E56+'G-2'!E65)+1.5*('Q-1'!E74+'Q-2'!E83) -> 0 | D11: =1.35*('G-1'!F56+'G-2'!F65)+1.5*('Q-1'!F74+'Q-2'!F83) -> -300.35865 | E11: =1.35*('G-1'!G56+'G-2'!G65)+1.5*('Q-1'!G74+'Q-2'!G83) -> 0 | F11: =1.35*('G-1'!H56+'G-2'!H65)+1.5*('Q-1'!H74+'Q-2'!H83) -> 0 | G11: =1.35*('G-1'!I56+'G-2'!I65)+1.5*('Q-1'!I74+'Q-2'!I83) -> 0 | H11: =1.35*('G-1'!J56+'G-2'!J65)+1.5*('Q-1'!J74+'Q-2'!J83) -> -241.70507
A12: 4 | B12: 1.25 | C12: =1.35*('G-1'!E57+'G-2'!E66)+1.5*('Q-1'!E75+'Q-2'!E84) -> 0 | D12: =1.35*('G-1'!F57+'G-2'!F66)+1.5*('Q-1'!F75+'Q-2'!F84) -> -215.79315 | E12: =1.35*('G-1'!G57+'G-2'!G66)+1.5*('Q-1'!G75+'Q-2'!G84) -> 0 | F12: =1.35*('G-1'!H57+'G-2'!H66)+1.5*('Q-1'!H75+'Q-2'!H84) -> 0 | G12: =1.35*('G-1'!I57+'G-2'!I66)+1.5*('Q-1'!I75+'Q-2'!I84) -> 0 | H12: =1.35*('G-1'!J57+'G-2'!J66)+1.5*('Q-1'!J75+'Q-2'!J84) -> 17.98461
A13: 4 | B13: 2.5 | C13: =1.35*('G-1'!E58+'G-2'!E67)+1.5*('Q-1'!E76+'Q-2'!E85) -> 0 | D13: =1.35*('G-1'!F58+'G-2'!F67)+1.5*('Q-1'!F76+'Q-2'!F85) -> -131.2305 | E13: =1.35*('G-1'!G58+'G-2'!G67)+1.5*('Q-1'!G76+'Q-2'!G85) -> 0 | F13: =1.35*('G-1'!H58+'G-2'!H67)+1.5*('Q-1'!H76+'Q-2'!H85) -> 0 | G13: =1.35*('G-1'!I58+'G-2'!I67)+1.5*('Q-1'!I76+'Q-2'!I85) -> 0 | H13: =1.35*('G-1'!J58+'G-2'!J67)+1.5*('Q-1'!J76+'Q-2'!J85) -> 192.58143
A14: 4 | B14: 3.75 | C14: =1.35*('G-1'!E59+'G-2'!E68)+1.5*('Q-1'!E77+'Q-2'!E86) -> 0 | D14: =1.35*('G-1'!F59+'G-2'!F68)+1.5*('Q-1'!F77+'Q-2'!F86) -> -46.66635 | E14: =1.35*('G-1'!G59+'G-2'!G68)+1.5*('Q-1'!G77+'Q-2'!G86) -> 0 | F14: =1.35*('G-1'!H59+'G-2'!H68)+1.5*('Q-1'!H77+'Q-2'!H86) -> 0 | G14: =1.35*('G-1'!I59+'G-2'!I68)+1.5*('Q-1'!I77+'Q-2'!I86) -> 0 | H14: =1.35*('G-1'!J59+'G-2'!J68)+1.5*('Q-1'!J77+'Q-2'!J86) -> 282.0858
A15: 4 | B15: 5 | C15: =1.35*('G-1'!E60+'G-2'!E69)+1.5*('Q-1'!E78+'Q-2'!E87) -> 0 | D15: =1.35*('G-1'!F60+'G-2'!F69)+1.5*('Q-1'!F78+'Q-2'!F87) -> 37.89915 | E15: =1.35*('G-1'!G60+'G-2'!G69)+1.5*('Q-1'!G78+'Q-2'!G87) -> 0 | F15: =1.35*('G-1'!H60+'G-2'!H69)+1.5*('Q-1'!H78+'Q-2'!H87) -> 0 | G15: =1.35*('G-1'!I60+'G-2'!I69)+1.5*('Q-1'!I78+'Q-2'!I87) -> 0 | H15: =1.35*('G-1'!J60+'G-2'!J69)+1.5*('Q-1'!J78+'Q-2'!J87) -> 286.49716
A16: 4 | B16: 6.25 | C16: =1.35*('G-1'!E61+'G-2'!E70)+1.5*('Q-1'!E79+'Q-2'!E88) -> 0 | D16: =1.35*('G-1'!F61+'G-2'!F70)+1.5*('Q-1'!F79+'Q-2'!F88) -> 122.4633 | E16: =1.35*('G-1'!G61+'G-2'!G70)+1.5*('Q-1'!G79+'Q-2'!G88) -> 0 | F16: =1.35*('G-1'!H61+'G-2'!H70)+1.5*('Q-1'!H79+'Q-2'!H88) -> 0 | G16: =1.35*('G-1'!I61+'G-2'!I70)+1.5*('Q-1'!I79+'Q-2'!I88) -> 0 | H16: =1.35*('G-1'!J61+'G-2'!J70)+1.5*('Q-1'!J79+'Q-2'!J88) -> 205.81566
A17: 4 | B17: 7.5 | C17: =1.35*('G-1'!E62+'G-2'!E71)+1.5*('Q-1'!E80+'Q-2'!E89) -> 0 | D17: =1.35*('G-1'!F62+'G-2'!F71)+1.5*('Q-1'!F80+'Q-2'!F89) -> 207.02595 | E17: =1.35*('G-1'!G62+'G-2'!G71)+1.5*('Q-1'!G80+'Q-2'!G89) -> 0 | F17: =1.35*('G-1'!H62+'G-2'!H71)+1.5*('Q-1'!H80+'Q-2'!H89) -> 0 | G17: =1.35*('G-1'!I62+'G-2'!I71)+1.5*('Q-1'!I80+'Q-2'!I89) -> 0 | H17: =1.35*('G-1'!J62+'G-2'!J71)+1.5*('Q-1'!J80+'Q-2'!J89) -> 40.04172
A18: 4 | B18: 8.75 | C18: =1.35*('G-1'!E63+'G-2'!E72)+1.5*('Q-1'!E81+'Q-2'!E90) -> 0 | D18: =1.35*('G-1'!F63+'G-2'!F72)+1.5*('Q-1'!F81+'Q-2'!F90) -> 291.5901 | E18: =1.35*('G-1'!G63+'G-2'!G72)+1.5*('Q-1'!G81+'Q-2'!G90) -> 0 | F18: =1.35*('G-1'!H63+'G-2'!H72)+1.5*('Q-1'!H81+'Q-2'!H90) -> 0 | G18: =1.35*('G-1'!I63+'G-2'!I72)+1.5*('Q-1'!I81+'Q-2'!I90) -> 0 | H18: =1.35*('G-1'!J63+'G-2'!J72)+1.5*('Q-1'!J81+'Q-2'!J90) -> -210.82538
A19: 4 | B19: 10 | C19: =1.35*('G-1'!E64+'G-2'!E73)+1.5*('Q-1'!E82+'Q-2'!E91) -> 0 | D19: =1.35*('G-1'!F64+'G-2'!F73)+1.5*('Q-1'!F82+'Q-2'!F91) -> 376.1556 | E19: =1.35*('G-1'!G64+'G-2'!G73)+1.5*('Q-1'!G82+'Q-2'!G91) -> 0 | F19: =1.35*('G-1'!H64+'G-2'!H73)+1.5*('Q-1'!H82+'Q-2'!H91) -> 0 | G19: =1.35*('G-1'!I64+'G-2'!I73)+1.5*('Q-1'!I82+'Q-2'!I91) -> 0 | H19: =1.35*('G-1'!J64+'G-2'!J73)+1.5*('Q-1'!J82+'Q-2'!J91) -> -546.78492
A20: 5 | B20: 0 | C20: =1.35*('G-1'!E101+'G-2'!E110)+1.5*('Q-1'!E119+'Q-2'!E128) -> 0 | D20: =1.35*('G-1'!F101+'G-2'!F110)+1.5*('Q-1'!F119+'Q-2'!F128) -> -376.1556 | E20: =1.35*('G-1'!G101+'G-2'!G110)+1.5*('Q-1'!G119+'Q-2'!G128) -> 0 | F20: =1.35*('G-1'!H101+'G-2'!H110)+1.5*('Q-1'!H119+'Q-2'!H128) -> 0 | G20: =1.35*('G-1'!I101+'G-2'!I110)+1.5*('Q-1'!I119+'Q-2'!I128) -> 0 | H20: =1.35*('G-1'!J101+'G-2'!J110)+1.5*('Q-1'!J119+'Q-2'!J128) -> -546.78492
A21: 5 | B21: 1.25 | C21: =1.35*('G-1'!E102+'G-2'!E111)+1.5*('Q-1'!E120+'Q-2'!E129) -> 0 | D21: =1.35*('G-1'!F102+'G-2'!F111)+1.5*('Q-1'!F120+'Q-2'!F129) -> -291.5901 | E21: =1.35*('G-1'!G102+'G-2'!G111)+1.5*('Q-1'!G120+'Q-2'!G129) -> 0 | F21: =1.35*('G-1'!H102+'G-2'!H111)+1.5*('Q-1'!H120+'Q-2'!H129) -> 0 | G21: =1.35*('G-1'!I102+'G-2'!I111)+1.5*('Q-1'!I120+'Q-2'!I129) -> 0 | H21: =1.35*('G-1'!J102+'G-2'!J111)+1.5*('Q-1'!J120+'Q-2'!J129) -> -210.82538
A22: 5 | B22: 2.5 | C22: =1.35*('G-1'!E103+'G-2'!E112)+1.5*('Q-1'!E121+'Q-2'!E130) -> 0 | D22: =1.35*('G-1'!F103+'G-2'!F112)+1.5*('Q-1'!F121+'Q-2'!F130) -> -207.02595 | E22: =1.35*('G-1'!G103+'G-2'!G112)+1.5*('Q-1'!G121+'Q-2'!G130) -> 0 | F22: =1.35*('G-1'!H103+'G-2'!H112)+1.5*('Q-1'!H121+'Q-2'!H130) -> 0 | G22: =1.35*('G-1'!I103+'G-2'!I112)+1.5*('Q-1'!I121+'Q-2'!I130) -> 0 | H22: =1.35*('G-1'!J103+'G-2'!J112)+1.5*('Q-1'!J121+'Q-2'!J130) -> 40.04172
A23: 5 | B23: 3.75 | C23: =1.35*('G-1'!E104+'G-2'!E113)+1.5*('Q-1'!E122+'Q-2'!E131) -> 0 | D23: =1.35*('G-1'!F104+'G-2'!F113)+1.5*('Q-1'!F122+'Q-2'!F131) -> -122.4633 | E23: =1.35*('G-1'!G104+'G-2'!G113)+1.5*('Q-1'!G122+'Q-2'!G131) -> 0 | F23: =1.35*('G-1'!H104+'G-2'!H113)+1.5*('Q-1'!H122+'Q-2'!H131) -> 0 | G23: =1.35*('G-1'!I104+'G-2'!I113)+1.5*('Q-1'!I122+'Q-2'!I131) -> 0 | H23: =1.35*('G-1'!J104+'G-2'!J113)+1.5*('Q-1'!J122+'Q-2'!J131) -> 205.81566
A24: 5 | B24: 5 | C24: =1.35*('G-1'!E105+'G-2'!E114)+1.5*('Q-1'!E123+'Q-2'!E132) -> 0 | D24: =1.35*('G-1'!F105+'G-2'!F114)+1.5*('Q-1'!F123+'Q-2'!F132) -> -37.89915 | E24: =1.35*('G-1'!G105+'G-2'!G114)+1.5*('Q-1'!G123+'Q-2'!G132) -> 0 | F24: =1.35*('G-1'!H105+'G-2'!H114)+1.5*('Q-1'!H123+'Q-2'!H132) -> 0 | G24: =1.35*('G-1'!I105+'G-2'!I114)+1.5*('Q-1'!I123+'Q-2'!I132) -> 0 | H24: =1.35*('G-1'!J105+'G-2'!J114)+1.5*('Q-1'!J123+'Q-2'!J132) -> 286.49716
A25: 5 | B25: 6.25 | C25: =1.35*('G-1'!E106+'G-2'!E115)+1.5*('Q-1'!E124+'Q-2'!E133) -> 0 | D25: =1.35*('G-1'!F106+'G-2'!F115)+1.5*('Q-1'!F124+'Q-2'!F133) -> 46.66635 | E25: =1.35*('G-1'!G106+'G-2'!G115)+1.5*('Q-1'!G124+'Q-2'!G133) -> 0 | F25: =1.35*('G-1'!H106+'G-2'!H115)+1.5*('Q-1'!H124+'Q-2'!H133) -> 0 | G25: =1.35*('G-1'!I106+'G-2'!I115)+1.5*('Q-1'!I124+'Q-2'!I133) -> 0 | H25: =1.35*('G-1'!J106+'G-2'!J115)+1.5*('Q-1'!J124+'Q-2'!J133) -> 282.0858
A26: 5 | B26: 7.5 | C26: =1.35*('G-1'!E107+'G-2'!E116)+1.5*('Q-1'!E125+'Q-2'!E134) -> 0 | D26: =1.35*('G-1'!F107+'G-2'!F116)+1.5*('Q-1'!F125+'Q-2'!F134) -> 131.2305 | E26: =1.35*('G-1'!G107+'G-2'!G116)+1.5*('Q-1'!G125+'Q-2'!G134) -> 0 | F26: =1.35*('G-1'!H107+'G-2'!H116)+1.5*('Q-1'!H125+'Q-2'!H134) -> 0 | G26: =1.35*('G-1'!I107+'G-2'!I116)+1.5*('Q-1'!I125+'Q-2'!I134) -> 0 | H26: =1.35*('G-1'!J107+'G-2'!J116)+1.5*('Q-1'!J125+'Q-2'!J134) -> 192.58143
A27: 5 | B27: 8.75 | C27: =1.35*('G-1'!E108+'G-2'!E117)+1.5*('Q-1'!E126+'Q-2'!E135) -> 0 | D27: =1.35*('G-1'!F108+'G-2'!F117)+1.5*('Q-1'!F126+'Q-2'!F135) -> 215.79315 | E27: =1.35*('G-1'!G108+'G-2'!G117)+1.5*('Q-1'!G126+'Q-2'!G135) -> 0 | F27: =1.35*('G-1'!H108+'G-2'!H117)+1.5*('Q-1'!H126+'Q-2'!H135) -> 0 | G27: =1.35*('G-1'!I108+'G-2'!I117)+1.5*('Q-1'!I126+'Q-2'!I135) -> 0 | H27: =1.35*('G-1'!J108+'G-2'!J117)+1.5*('Q-1'!J126+'Q-2'!J135) -> 17.98461
A28: 5 | B28: 10 | C28: =1.35*('G-1'!E109+'G-2'!E118)+1.5*('Q-1'!E127+'Q-2'!E136) -> 0 | D28: =1.35*('G-1'!F109+'G-2'!F118)+1.5*('Q-1'!F127+'Q-2'!F136) -> 300.35865 | E28: =1.35*('G-1'!G109+'G-2'!G118)+1.5*('Q-1'!G127+'Q-2'!G136) -> 0 | F28: =1.35*('G-1'!H109+'G-2'!H118)+1.5*('Q-1'!H127+'Q-2'!H136) -> 0 | G28: =1.35*('G-1'!I109+'G-2'!I118)+1.5*('Q-1'!I127+'Q-2'!I136) -> 0 | H28: =1.35*('G-1'!J109+'G-2'!J118)+1.5*('Q-1'!J127+'Q-2'!J136) -> -241.70507

Sheet Δ-Ε
A1: Frame | B1: Station | C1: P | D1: V2 | E1: V3 | F1: T | G1: M2 | H1: M3
A2: 1 | B2: 0 | C2: =1.35*'G-1'!E5+'G-2'!E8+1.5*'Q-1'!E11 -> -311.6627 | D2: =1.35*'G-1'!F5+'G-2'!F8+1.5*'Q-1'!F11 -> -69.68875 | E2: =1.35*'G-1'!G5+'G-2'!G8+1.5*'Q-1'!G11 -> 0 | F2: =1.35*'G-1'!H5+'G-2'!H8+1.5*'Q-1'!H11 -> 0 | G2: =1.35*'G-1'!I5+'G-2'!I8+1.5*'Q-1'!I11 -> 0 | H2: =1.35*'G-1'!J5+'G-2'!J8+1.5*'Q-1'!J11 -> -109.43708
A3: 1 | B3: 3.25 | C3: =1.35*'G-1'!E6+'G-2'!E9+1.5*'Q-1'!E12 -> -311.6627 | D3: =1.35*'G-1'!F6+'G-2'!F9+1.5*'Q-1'!F12 -> -69.68875 | E3: =1.35*'G-1'!G6+'G-2'!G9+1.5*'Q-1'!G12 -> 0 | F3: =1.35*'G-1'!H6+'G-2'!H9+1.5*'Q-1'!H12 -> 0 | G3: =1.35*'G-1'!I6+'G-2'!I9+1.5*'Q-1'!I12 -> 0 | H3: =1.35*'G-1'!J6+'G-2'!J9+1.5*'Q-1'!J12 -> 71.75331
A4: 1 | B4: 6.5 | C4: =1.35*'G-1'!E7+'G-2'!E10+1.5*'Q-1'!E13 -> -311.6627 | D4: =1.35*'G-1'!F7+'G-2'!F10+1.5*'Q-1'!F13 -> -69.68875 | E4: =1.35*'G-1'!G7+'G-2'!G10+1.5*'Q-1'!G13 -> 0 | F4: =1.35*'G-1'!H7+'G-2'!H10+1.5*'Q-1'!H13 -> 0 | G4: =1.35*'G-1'!I7+'G-2'!I10+1.5*'Q-1'!I13 -> 0 | H4: =1.35*'G-1'!J7+'G-2'!J10+1.5*'Q-1'!J13 -> 252.94357
A5: 2 | B5: 0 | C5: =1.35*'G-1'!E20+'G-2'!E23+1.5*'Q-1'!E26 -> -554.7016 | D5: =1.35*'G-1'!F20+'G-2'!F23+1.5*'Q-1'!F26 -> 38.283 | E5: =1.35*'G-1'!G20+'G-2'!G23+1.5*'Q-1'!G26 -> 0 | F5: =1.35*'G-1'!H20+'G-2'!H23+1.5*'Q-1'!H26 -> 0 | G5: =1.35*'G-1'!I20+'G-2'!I23+1.5*'Q-1'!I26 -> 0 | H5: =1.35*'G-1'!J20+'G-2'!J23+1.5*'Q-1'!J26 -> 71.334685
A6: 2 | B6: 3.25 | C6: =1.35*'G-1'!E21+'G-2'!E24+1.5*'Q-1'!E27 -> -554.7016 | D6: =1.35*'G-1'!F21+'G-2'!F24+1.5*'Q-1'!F27 -> 38.283 | E6: =1.35*'G-1'!G21+'G-2'!G24+1.5*'Q-1'!G27 -> 0 | F6: =1.35*'G-1'!H21+'G-2'!H24+1.5*'Q-1'!H27 -> 0 | G6: =1.35*'G-1'!I21+'G-2'!I24+1.5*'Q-1'!I27 -> 0 | H6: =1.35*'G-1'!J21+'G-2'!J24+1.5*'Q-1'!J27 -> -28.2005
A7: 2 | B7: 6.5 | C7: =1.35*'G-1'!E22+'G-2'!E25+1.5*'Q-1'!E28 -> -554.7016 | D7: =1.35*'G-1'!F22+'G-2'!F25+1.5*'Q-1'!F28 -> 38.283 | E7: =1.35*'G-1'!G22+'G-2'!G25+1.5*'Q-1'!G28 -> 0 | F7: =1.35*'G-1'!H22+'G-2'!H25+1.5*'Q-1'!H28 -> 0 | G7: =1.35*'G-1'!I22+'G-2'!I25+1.5*'Q-1'!I28 -> 0 | H7: =1.35*'G-1'!J22+'G-2'!J25+1.5*'Q-1'!J28 -> -127.73572
A8: 3 | B8: 0 | C8: =1.35*'G-1'!E35+'G-2'!E38+1.5*'Q-1'!E41 -> -131.26495 | D8: =1.35*'G-1'!F35+'G-2'!F38+1.5*'Q-1'!F41 -> 31.40575 | E8: =1.35*'G-1'!G35+'G-2'!G38+1.5*'Q-1'!G41 -> 0 | F8: =1.35*'G-1'!H35+'G-2'!H38+1.5*'Q-1'!H41 -> 0 | G8: =1.35*'G-1'!I35+'G-2'!I38+1.5*'Q-1'!I41 -> 0 | H8: =1.35*'G-1'!J35+'G-2'!J38+1.5*'Q-1'!J41 -> 59.820855
A9: 3 | B9: 3.25 | C9: =1.35*'G-1'!E36+'G-2'!E39+1.5*'Q-1'!E42 -> -131.26495 | D9: =1.35*'G-1'!F36+'G-2'!F39+1.5*'Q-1'!F42 -> 31.40575 | E9: =1.35*'G-1'!G36+'G-2'!G39+1.5*'Q-1'!G42 -> 0 | F9: =1.35*'G-1'!H36+'G-2'!H39+1.5*'Q-1'!H42 -> 0 | G9: =1.35*'G-1'!I36+'G-2'!I39+1.5*'Q-1'!I42 -> 0 | H9: =1.35*'G-1'!J36+'G-2'!J39+1.5*'Q-1'!J42 -> -21.83432
A10: 3 | B10: 6.5 | C10: =1.35*'G-1'!E37+'G-2'!E40+1.5*'Q-1'!E43 -> -131.26495 | D10: =1.35*'G-1'!F37+'G-2'!F40+1.5*'Q-1'!F43 -> 31.40575 | E10: =1.35*'G-1'!G37+'G-2'!G40+1.5*'Q-1'!G43 -> 0 | F10: =1.35*'G-1'!H37+'G-2'!H40+1.5*'Q-1'!H43 -> 0 | G10: =1.35*'G-1'!I37+'G-2'!I40+1.5*'Q-1'!I43 -> 0 | H10: =1.35*'G-1'!J37+'G-2'!J40+1.5*'Q-1'!J43 -> -103.4894
A11: 4 | B11: 0 | C11: =1.35*'G-1'!E56+'G-2'!E65+1.5*'Q-1'!E74 -> 0 | D11: =1.35*'G-1'!F56+'G-2'!F65+1.5*'Q-1'!F74 -> -311.6627 | E11: =1.35*'G-1'!G56+'G-2'!G65+1.5*'Q-1'!G74 -> 0 | F11: =1.35*'G-1'!H56+'G-2'!H65+1.5*'Q-1'!H74 -> 0 | G11: =1.35*'G-1'!I56+'G-2'!I65+1.5*'Q-1'!I74 -> 0 | H11: =1.35*'G-1'!J56+'G-2'!J65+1.5*'Q-1'!J74 -> -252.94357
A12: 4 | B12: 1.25 | C12: =1.35*'G-1'!E57+'G-2'!E66+1.5*'Q-1'!E75 -> 0 | D12: =1.35*'G-1'!F57+'G-2'!F66+1.5*'Q-1'!F75 -> -227.0972 | E12: =1.35*'G-1'!G57+'G-2'!G66+1.5*'Q-1'!G75 -> 0 | F12: =1.35*'G-1'!H57+'G-2'!H66+1.5*'Q-1'!H75 -> 0 | G12: =1.35*'G-1'!I57+'G-2'!I66+1.5*'Q-1'!I75 -> 0 | H12: =1.35*'G-1'!J57+'G-2'!J66+1.5*'Q-1'!J75 -> 18.120405
A13: 4 | B13: 2.5 | C13: =1.35*'G-1'!E58+'G-2'!E67+1.5*'Q-1'!E76 -> 0 | D13: =1.35*'G-1'!F58+'G-2'!F67+1.5*'Q-1'!F76 -> -142.53455 | E13: =1.35*'G-1'!G58+'G-2'!G67+1.5*'Q-1'!G76 -> 0 | F13: =1.35*'G-1'!H58+'G-2'!H67+1.5*'Q-1'!H76 -> 0 | G13: =1.35*'G-1'!I58+'G-2'!I67+1.5*'Q-1'!I76 -> 0 | H13: =1.35*'G-1'!J58+'G-2'!J67+1.5*'Q-1'!J76 -> 204.09156
A14: 4 | B14: 3.75 | C14: =1.35*'G-1'!E59+'G-2'!E68+1.5*'Q-1'!E77 -> 0 | D14: =1.35*'G-1'!F59+'G-2'!F68+1.5*'Q-1'!F77 -> -57.9704 | E14: =1.35*'G-1'!G59+'G-2'!G68+1.5*'Q-1'!G77 -> 0 | F14: =1.35*'G-1'!H59+'G-2'!H68+1.5*'Q-1'!H77 -> 0 | G14: =1.35*'G-1'!I59+'G-2'!I68+1.5*'Q-1'!I77 -> 0 | H14: =1.35*'G-1'!J59+'G-2'!J68+1.5*'Q-1'!J77 -> 304.97023
A15: 4 | B15: 5 | C15: =1.35*'G-1'!E60+'G-2'!E69+1.5*'Q-1'!E78 -> 0 | D15: =1.35*'G-1'!F60+'G-2'!F69+1.5*'Q-1'!F78 -> 26.5951 | E15: =1.35*'G-1'!G60+'G-2'!G69+1.5*'Q-1'!G78 -> 0 | F15: =1.35*'G-1'!H60+'G-2'!H69+1.5*'Q-1'!H78 -> 0 | G15: =1.35*'G-1'!I60+'G-2'!I69+1.5*'Q-1'!I78 -> 0 | H15: =1.35*'G-1'!J60+'G-2'!J69+1.5*'Q-1'!J78 -> 320.7559
A16: 4 | B16: 6.25 | C16: =1.35*'G-1'!E61+'G-2'!E70+1.5*'Q-1'!E79 -> 0 | D16: =1.35*'G-1'!F61+'G-2'!F70+1.5*'Q-1'!F79 -> 111.15925 | E16: =1.35*'G-1'!G61+'G-2'!G70+1.5*'Q-1'!G79 -> 0 | F16: =1.35*'G-1'!H61+'G-2'!H70+1.5*'Q-1'!H79 -> 0 | G16: =1.35*'G-1'!I61+'G-2'!I70+1.5*'Q-1'!I79 -> 0 | H16: =1.35*'G-1'!J61+'G-2'!J70+1.5*'Q-1'!J79 -> 251.44873
A17: 4 | B17: 7.5 | C17: =1.35*'G-1'!E62+'G-2'!E71+1.5*'Q-1'!E80 -> 0 | D17: =1.35*'G-1'!F62+'G-2'!F71+1.5*'Q-1'!F80 -> 195.7219 | E17: =1.35*'G-1'!G62+'G-2'!G71+1.5*'Q-1'!G80 -> 0 | F17: =1.35*'G-1'!H62+'G-2'!H71+1.5*'Q-1'!H80 -> 0 | G17: =1.35*'G-1'!I62+'G-2'!I71+1.5*'Q-1'!I80 -> 0 | H17: =1.35*'G-1'!J62+'G-2'!J71+1.5*'Q-1'!J80 -> 97.049085
A18: 4 | B18: 8.75 | C18: =1.35*'G-1'!E63+'G-2'!E72+1.5*'Q-1'!E81 -> 0 | D18: =1.35*'G-1'!F63+'G-2'!F72+1.5*'Q-1'!F81 -> 280.28605 | E18: =1.35*'G-1'!G63+'G-2'!G72+1.5*'Q-1'!G81 -> 0 | F18: =1.35*'G-1'!H63+'G-2'!H72+1.5*'Q-1'!H81 -> 0 | G18: =1.35*'G-1'!I63+'G-2'!I72+1.5*'Q-1'!I81 -> 0 | H18: =1.35*'G-1'!J63+'G-2'!J72+1.5*'Q-1'!J81 -> -142.44368
A19: 4 | B19: 10 | C19: =1.35*'G-1'!E64+'G-2'!E73+1.5*'Q-1'!E82 -> 0 | D19: =1.35*'G-1'!F64+'G-2'!F73+1.5*'Q-1'!F82 -> 364.85155 | E19: =1.35*'G-1'!G64+'G-2'!G73+1.5*'Q-1'!G82 -> 0 | F19: =1.35*'G-1'!H64+'G-2'!H73+1.5*'Q-1'!H82 -> 0 | G19: =1.35*'G-1'!I64+'G-2'!I73+1.5*'Q-1'!I82 -> 0 | H19: =1.35*'G-1'!J64+'G-2'!J73+1.5*'Q-1'!J82 -> -467.02892
A20: 5 | B20: 0 | C20: =1.35*'G-1'!E101+'G-2'!E110+1.5*'Q-1'!E119 -> 0 | D20: =1.35*'G-1'!F101+'G-2'!F110+1.5*'Q-1'!F119 -> -189.85005 | E20: =1.35*'G-1'!G101+'G-2'!G110+1.5*'Q-1'!G119 -> 0 | F20: =1.35*'G-1'!H101+'G-2'!H110+1.5*'Q-1'!H119 -> 0 | G20: =1.35*'G-1'!I101+'G-2'!I110+1.5*'Q-1'!I119 -> 0 | H20: =1.35*'G-1'!J101+'G-2'!J110+1.5*'Q-1'!J119 -> -339.2932
A21: 5 | B21: 1.25 | C21: =1.35*'G-1'!E102+'G-2'!E111+1.5*'Q-1'!E120 -> 0 | D21: =1.35*'G-1'!F102+'G-2'!F111+1.5*'Q-1'!F120 -> -149.71005 | E21: =1.35*'G-1'!G102+'G-2'!G111+1.5*'Q-1'!G120 -> 0 | F21: =1.35*'G-1'!H102+'G-2'!H111+1.5*'Q-1'!H120 -> 0 | G21: =1.35*'G-1'!I102+'G-2'!I111+1.5*'Q-1'!I120 -> 0 | H21: =1.35*'G-1'!J102+'G-2'!J111+1.5*'Q-1'!J120 -> -168.4522
A22: 5 | B22: 2.5 | C22: =1.35*'G-1'!E103+'G-2'!E112+1.5*'Q-1'!E121 -> 0 | D22: =1.35*'G-1'!F103+'G-2'!F112+1.5*'Q-1'!F121 -> -109.57105 | E22: =1.35*'G-1'!G103+'G-2'!G112+1.5*'Q-1'!G121 -> 0 | F22: =1.35*'G-1'!H103+'G-2'!H112+1.5*'Q-1'!H121 -> 0 | G22: =1.35*'G-1'!I103+'G-2'!I112+1.5*'Q-1'!I121 -> 0 | H22: =1.35*'G-1'!J103+'G-2'!J112+1.5*'Q-1'!J121 -> -38.001165
A23: 5 | B23: 3.75 | C23: =1.35*'G-1'!E104+'G-2'!E113+1.5*'Q-1'!E122 -> 0 | D23: =1.35*'G-1'!F104+'G-2'!F113+1.5*'Q-1'!F122 -> -69.43205 | E23: =1.35*'G-1'!G104+'G-2'!G113+1.5*'Q-1'!G122 -> 0 | F23: =1.35*'G-1'!H104+'G-2'!H113+1.5*'Q-1'!H122 -> 0 | G23: =1.35*'G-1'!I104+'G-2'!I113+1.5*'Q-1'!I122 -> 0 | H23: =1.35*'G-1'!J104+'G-2'!J113+1.5*'Q-1'!J122 -> 52.059535
A24: 5 | B24: 5 | C24: =1.35*'G-1'!E105+'G-2'!E114+1.5*'Q-1'!E123 -> 0 | D24: =1.35*'G-1'!F105+'G-2'!F114+1.5*'Q-1'!F123 -> -29.29305 | E24: =1.35*'G-1'!G105+'G-2'!G114+1.5*'Q-1'!G123 -> 0 | F24: =1.35*'G-1'!H105+'G-2'!H114+1.5*'Q-1'!H123 -> 0 | G24: =1.35*'G-1'!I105+'G-2'!I114+1.5*'Q-1'!I123 -> 0 | H24: =1.35*'G-1'!J105+'G-2'!J114+1.5*'Q-1'!J123 -> 101.73017
A25: 5 | B25: 6.25 | C25: =1.35*'G-1'!E106+'G-2'!E115+1.5*'Q-1'!E124 -> 0 | D25: =1.35*'G-1'!F106+'G-2'!F115+1.5*'Q-1'!F124 -> 10.84695 | E25: =1.35*'G-1'!G106+'G-2'!G115+1.5*'Q-1'!G124 -> 0 | F25: =1.35*'G-1'!H106+'G-2'!H115+1.5*'Q-1'!H124 -> 0 | G25: =1.35*'G-1'!I106+'G-2'!I115+1.5*'Q-1'!I124 -> 0 | H25: =1.35*'G-1'!J106+'G-2'!J115+1.5*'Q-1'!J124 -> 111.01057
A26: 5 | B26: 7.5 | C26: =1.35*'G-1'!E107+'G-2'!E116+1.5*'Q-1'!E125 -> 0 | D26: =1.35*'G-1'!F107+'G-2'!F116+1.5*'Q-1'!F125 -> 50.98595 | E26: =1.35*'G-1'!G107+'G-2'!G116+1.5*'Q-1'!G125 -> 0 | F26: =1.35*'G-1'!H107+'G-2'!H116+1.5*'Q-1'!H125 -> 0 | G26: =1.35*'G-1'!I107+'G-2'!I116+1.5*'Q-1'!I125 -> 0 | H26: =1.35*'G-1'!J107+'G-2'!J116+1.5*'Q-1'!J125 -> 79.90067
A27: 5 | B27: 8.75 | C27: =1.35*'G-1'!E108+'G-2'!E117+1.5*'Q-1'!E126 -> 0 | D27: =1.35*'G-1'!F108+'G-2'!F117+1.5*'Q-1'!F126 -> 91.12495 | E27: =1.35*'G-1'!G108+'G-2'!G117+1.5*'Q-1'!G126 -> 0 | F27: =1.35*'G-1'!H108+'G-2'!H117+1.5*'Q-1'!H126 -> 0 | G27: =1.35*'G-1'!I108+'G-2'!I117+1.5*'Q-1'!I126 -> 0 | H27: =1.35*'G-1'!J108+'G-2'!J117+1.5*'Q-1'!J126 -> 8.400805
A28: 5 | B28: 10 | C28: =1.35*'G-1'!E109+'G-2'!E118+1.5*'Q-1'!E127 -> 0 | D28: =1.35*'G-1'!F109+'G-2'!F118+1.5*'Q-1'!F127 -> 131.26495 | E28: =1.35*'G-1'!G109+'G-2'!G118+1.5*'Q-1'!G127 -> 0 | F28: =1.35*'G-1'!H109+'G-2'!H118+1.5*'Q-1'!H127 -> 0 | G28: =1.35*'G-1'!I109+'G-2'!I118+1.5*'Q-1'!I127 -> 0 | H28: =1.35*'G-1'!J109+'G-2'!J118+1.5*'Q-1'!J127 -> -103.4894

Sheet Ε-Δ
A1: Frame | B1: Station | C1: P | D1: V2 | E1: V3 | F1: T | G1: M2 | H1: M3
A2: 1 | B2: 0 | C2: ='G-1'!E5+1.35*'G-2'!E8+1.5*'Q-2'!E14 -> -131.26495 | D2: ='G-1'!F5+1.35*'G-2'!F8+1.5*'Q-2'!F14 -> -31.40575 | E2: ='G-1'!G5+1.35*'G-2'!G8+1.5*'Q-2'!G14 -> 0 | F2: ='G-1'!H5+1.35*'G-2'!H8+1.5*'Q-2'!H14 -> 0 | G2: ='G-1'!I5+1.35*'G-2'!I8+1.5*'Q-2'!I14 -> 0 | H2: ='G-1'!J5+1.35*'G-2'!J8+1.5*'Q-2'!J14 -> -59.820855
A3: 1 | B3: 3.25 | C3: ='G-1'!E6+1.35*'G-2'!E9+1.5*'Q-2'!E15 -> -131.26495 | D3: ='G-1'!F6+1.35*'G-2'!F9+1.5*'Q-2'!F15 -> -31.40575 | E3: ='G-1'!G6+1.35*'G-2'!G9+1.5*'Q-2'!G15 -> 0 | F3: ='G-1'!H6+1.35*'G-2'!H9+1.5*'Q-2'!H15 -> 0 | G3: ='G-1'!I6+1.35*'G-2'!I9+1.5*'Q-2'!I15 -> 0 | H3: ='G-1'!J6+1.35*'G-2'!J9+1.5*'Q-2'!J15 -> 21.83432
A4: 1 | B4: 6.5 | C4: ='G-1'!E7+1.35*'G-2'!E10+1.5*'Q-2'!E16 -> -131.26495 | D4: ='G-1'!F7+1.35*'G-2'!F10+1.5*'Q-2'!F16 -> -31.40575 | E4: ='G-1'!G7+1.35*'G-2'!G10+1.5*'Q-2'!G16 -> 0 | F4: ='G-1'!H7+1.35*'G-2'!H10+1.5*'Q-2'!H16 -> 0 | G4: ='G-1'!I7+1.35*'G-2'!I10+1.5*'Q-2'!I16 -> 0 | H4: ='G-1'!J7+1.35*'G-2'!J10+1.5*'Q-2'!J16 -> 103.4894
A5: 2 | B5: 0 | C5: ='G-1'!E20+1.35*'G-2'!E23+1.5*'Q-2'!E29 -> -554.7016 | D5: ='G-1'!F20+1.35*'G-2'!F23+1.5*'Q-2'!F29 -> -38.283 | E5: ='G-1'!G20+1.35*'G-2'!G23+1.5*'Q-2'!G29 -> 0 | F5: ='G-1'!H20+1.35*'G-2'!H23+1.5*'Q-2'!H29 -> 0 | G5: ='G-1'!I20+1.35*'G-2'!I23+1.5*'Q-2'!I29 -> 0 | H5: ='G-1'!J20+1.35*'G-2'!J23+1.5*'Q-2'!J29 -> -71.334685
A6: 2 | B6: 3.25 | C6: ='G-1'!E21+1.35*'G-2'!E24+1.5*'Q-2'!E30 -> -554.7016 | D6: ='G-1'!F21+1.35*'G-2'!F24+1.5*'Q-2'!F30 -> -38.283 | E6: ='G-1'!G21+1.35*'G-2'!G24+1.5*'Q-2'!G30 -> 0 | F6: ='G-1'!H21+1.35*'G-2'!H24+1.5*'Q-2'!H30 -> 0 | G6: ='G-1'!I21+1.35*'G-2'!I24+1.5*'Q-2'!I30 -> 0 | H6: ='G-1'!J21+1.35*'G-2'!J24+1.5*'Q-2'!J30 -> 28.2005
A7: 2 | B7: 6.5 | C7: ='G-1'!E22+1.35*'G-2'!E25+1.5*'Q-2'!E31 -> -554.7016 | D7: ='G-1'!F22+1.35*'G-2'!F25+1.5*'Q-2'!F31 -> -38.283 | E7: ='G-1'!G22+1.35*'G-2'!G25+1.5*'Q-2'!G31 -> 0 | F7: ='G-1'!H22+1.35*'G-2'!H25+1.5*'Q-2'!H31 -> 0 | G7: ='G-1'!I22+1.35*'G-2'!I25+1.5*'Q-2'!I31 -> 0 | H7: ='G-1'!J22+1.35*'G-2'!J25+1.5*'Q-2'!J31 -> 127.73572
A8: 3 | B8: 0 | C8: ='G-1'!E35+1.35*'G-2'!E38+1.5*'Q-2'!E44 -> -311.6627 | D8: ='G-1'!F35+1.35*'G-2'!F38+1.5*'Q-2'!F44 -> 69.68875 | E8: ='G-1'!G35+1.35*'G-2'!G38+1.5*'Q-2'!G44 -> 0 | F8: ='G-1'!H35+1.35*'G-2'!H38+1.5*'Q-2'!H44 -> 0 | G8: ='G-1'!I35+1.35*'G-2'!I38+1.5*'Q-2'!I44 -> 0 | H8: ='G-1'!J35+1.35*'G-2'!J38+1.5*'Q-2'!J44 -> 109.43708
A9: 3 | B9: 3.25 | C9: ='G-1'!E36+1.35*'G-2'!E39+1.5*'Q-2'!E45 -> -311.6627 | D9: ='G-1'!F36+1.35*'G-2'!F39+1.5*'Q-2'!F45 -> 69.68875 | E9: ='G-1'!G36+1.35*'G-2'!G39+1.5*'Q-2'!G45 -> 0 | F9: ='G-1'!H36+1.35*'G-2'!H39+1.5*'Q-2'!H45 -> 0 | G9: ='G-1'!I36+1.35*'G-2'!I39+1.5*'Q-2'!I45 -> 0 | H9: ='G-1'!J36+1.35*'G-2'!J39+1.5*'Q-2'!J45 -> -71.75331
A10: 3 | B10: 6.5 | C10: ='G-1'!E37+1.35*'G-2'!E40+1.5*'Q-2'!E46 -> -311.6627 | D10: ='G-1'!F37+1.35*'G-2'!F40+1.5*'Q-2'!F46 -> 69.68875 | E10: ='G-1'!G37+1.35*'G-2'!G40+1.5*'Q-2'!G46 -> 0 | F10: ='G-1'!H37+1.35*'G-2'!H40+1.5*'Q-2'!H46 -> 0 | G10: ='G-1'!I37+1.35*'G-2'!I40+1.5*'Q-2'!I46 -> 0 | H10: ='G-1'!J37+1.35*'G-2'!J40+1.5*'Q-2'!J46 -> -252.94357
A11: 4 | B11: 0 | C11: ='G-1'!E56+1.35*'G-2'!E65+1.5*'Q-2'!E83 -> 0 | D11: ='G-1'!F56+1.35*'G-2'!F65+1.5*'Q-2'!F83 -> -131.26495 | E11: ='G-1'!G56+1.35*'G-2'!G65+1.5*'Q-2'!G83 -> 0 | F11: ='G-1'!H56+1.35*'G-2'!H65+1.5*'Q-2'!H83 -> 0 | G11: ='G-1'!I56+1.35*'G-2'!I65+1.5*'Q-2'!I83 -> 0 | H11: ='G-1'!J56+1.35*'G-2'!J65+1.5*'Q-2'!J83 -> -103.4894
A12: 4 | B12: 1.25 | C12: ='G-1'!E57+1.35*'G-2'!E66+1.5*'Q-2'!E84 -> 0 | D12: ='G-1'!F57+1.35*'G-2'!F66+1.5*'Q-2'!F84 -> -91.12495 | E12: ='G-1'!G57+1.35*'G-2'!G66+1.5*'Q-2'!G84 -> 0 | F12: ='G-1'!H57+1.35*'G-2'!H66+1.5*'Q-2'!H84 -> 0 | G12: ='G-1'!I57+1.35*'G-2'!I66+1.5*'Q-2'!I84 -> 0 | H12: ='G-1'!J57+1.35*'G-2'!J66+1.5*'Q-2'!J84 -> 8.400805
A13: 4 | B13: 2.5 | C13: ='G-1'!E58+1.35*'G-2'!E67+1.5*'Q-2'!E85 -> 0 | D13: ='G-1'!F58+1.35*'G-2'!F67+1.5*'Q-2'!F85 -> -50.98595 | E13: ='G-1'!G58+1.35*'G-2'!G67+1.5*'Q-2'!G85 -> 0 | F13: ='G-1'!H58+1.35*'G-2'!H67+1.5*'Q-2'!H85 -> 0 | G13: ='G-1'!I58+1.35*'G-2'!I67+1.5*'Q-2'!I85 -> 0 | H13: ='G-1'!J58+1.35*'G-2'!J67+1.5*'Q-2'!J85 -> 79.90067
A14: 4 | B14: 3.75 | C14: ='G-1'!E59+1.35*'G-2'!E68+1.5*'Q-2'!E86 -> 0 | D14: ='G-1'!F59+1.35*'G-2'!F68+1.5*'Q-2'!F86 -> -10.84695 | E14: ='G-1'!G59+1.35*'G-2'!G68+1.5*'Q-2'!G86 -> 0 | F14: ='G-1'!H59+1.35*'G-2'!H68+1.5*'Q-2'!H86 -> 0 | G14: ='G-1'!I59+1.35*'G-2'!I68+1.5*'Q-2'!I86 -> 0 | H14: ='G-1'!J59+1.35*'G-2'!J68+1.5*'Q-2'!J86 -> 111.01057
A15: 4 | B15: 5 | C15: ='G-1'!E60+1.35*'G-2'!E69+1.5*'Q-2'!E87 -> 0 | D15: ='G-1'!F60+1.35*'G-2'!F69+1.5*'Q-2'!F87 -> 29.29305 | E15: ='G-1'!G60+1.35*'G-2'!G69+1.5*'Q-2'!G87 -> 0 | F15: ='G-1'!H60+1.35*'G-2'!H69+1.5*'Q-2'!H87 -> 0 | G15: ='G-1'!I60+1.35*'G-2'!I69+1.5*'Q-2'!I87 -> 0 | H15: ='G-1'!J60+1.35*'G-2'!J69+1.5*'Q-2'!J87 -> 101.73017
A16: 4 | B16: 6.25 | C16: ='G-1'!E61+1.35*'G-2'!E70+1.5*'Q-2'!E88 -> 0 | D16: ='G-1'!F61+1.35*'G-2'!F70+1.5*'Q-2'!F88 -> 69.43205 | E16: ='G-1'!G61+1.35*'G-2'!G70+1.5*'Q-2'!G88 -> 0 | F16: ='G-1'!H61+1.35*'G-2'!H70+1.5*'Q-2'!H88 -> 0 | G16: ='G-1'!I61+1.35*'G-2'!I70+1.5*'Q-2'!I88 -> 0 | H16: ='G-1'!J61+1.35*'G-2'!J70+1.5*'Q-2'!J88 -> 52.059535
A17: 4 | B17: 7.5 | C17: ='G-1'!E62+1.35*'G-2'!E71+1.5*'Q-2'!E89 -> 0 | D17: ='G-1'!F62+1.35*'G-2'!F71+1.5*'Q-2'!F89 -> 109.57105 | E17: ='G-1'!G62+1.35*'G-2'!G71+1.5*'Q-2'!G89 -> 0 | F17: ='G-1'!H62+1.35*'G-2'!H71+1.5*'Q-2'!H89 -> 0 | G17: ='G-1'!I62+1.35*'G-2'!I71+1.5*'Q-2'!I89 -> 0 | H17: ='G-1'!J62+1.35*'G-2'!J71+1.5*'Q-2'!J89 -> -38.001165
A18: 4 | B18: 8.75 | C18: ='G-1'!E63+1.35*'G-2'!E72+1.5*'Q-2'!E90 -> 0 | D18: ='G-1'!F63+1.35*'G-2'!F72+1.5*'Q-2'!F90 -> 149.71005 | E18: ='G-1'!G63+1.35*'G-2'!G72+1.5*'Q-2'!G90 -> 0 | F18: ='G-1'!H63+1.35*'G-2'!H72+1.5*'Q-2'!H90 -> 0 | G18: ='G-1'!I63+1.35*'G-2'!I72+1.5*'Q-2'!I90 -> 0 | H18: ='G-1'!J63+1.35*'G-2'!J72+1.5*'Q-2'!J90 -> -168.4522
A19: 4 | B19: 10 | C19: ='G-1'!E64+1.35*'G-2'!E73+1.5*'Q-2'!E91 -> 0 | D19: ='G-1'!F64+1.35*'G-2'!F73+1.5*'Q-2'!F91 -> 189.85005 | E19: ='G-1'!G64+1.35*'G-2'!G73+1.5*'Q-2'!G91 -> 0 | F19: ='G-1'!H64+1.35*'G-2'!H73+1.5*'Q-2'!H91 -> 0 | G19: ='G-1'!I64+1.35*'G-2'!I73+1.5*'Q-2'!I91 -> 0 | H19: ='G-1'!J64+1.35*'G-2'!J73+1.5*'Q-2'!J91 -> -339.2932
A20: 5 | B20: 0 | C20: ='G-1'!E101+1.35*'G-2'!E110+1.5*'Q-2'!E128 -> 0 | D20: ='G-1'!F101+1.35*'G-2'!F110+1.5*'Q-2'!F128 -> -364.85155 | E20: ='G-1'!G101+1.35*'G-2'!G110+1.5*'Q-2'!G128 -> 0 | F20: ='G-1'!H101+1.35*'G-2'!H110+1.5*'Q-2'!H128 -> 0 | G20: ='G-1'!I101+1.35*'G-2'!I110+1.5*'Q-2'!I128 -> 0 | H20: ='G-1'!J101+1.35*'G-2'!J110+1.5*'Q-2'!J128 -> -467.02892
A21: 5 | B21: 1.25 | C21: ='G-1'!E102+1.35*'G-2'!E111+1.5*'Q-2'!E129 -> 0 | D21: ='G-1'!F102+1.35*'G-2'!F111+1.5*'Q-2'!F129 -> -280.28605 | E21: ='G-1'!G102+1.35*'G-2'!G111+1.5*'Q-2'!G129 -> 0 | F21: ='G-1'!H102+1.35*'G-2'!H111+1.5*'Q-2'!H129 -> 0 | G21: ='G-1'!I102+1.35*'G-2'!I111+1.5*'Q-2'!I129 -> 0 | H21: ='G-1'!J102+1.35*'G-2'!J111+1.5*'Q-2'!J129 -> -142.44368
A22: 5 | B22: 2.5 | C22: ='G-1'!E103+1.35*'G-2'!E112+1.5*'Q-2'!E130 -> 0 | D22: ='G-1'!F103+1.35*'G-2'!F112+1.5*'Q-2'!F130 -> -195.7219 | E22: ='G-1'!G103+1.35*'G-2'!G112+1.5*'Q-2'!G130 -> 0 | F22: ='G-1'!H103+1.35*'G-2'!H112+1.5*'Q-2'!H130 -> 0 | G22: ='G-1'!I103+1.35*'G-2'!I112+1.5*'Q-2'!I130 -> 0 | H22: ='G-1'!J103+1.35*'G-2'!J112+1.5*'Q-2'!J130 -> 97.049085
A23: 5 | B23: 3.75 | C23: ='G-1'!E104+1.35*'G-2'!E113+1.5*'Q-2'!E131 -> 0 | D23: ='G-1'!F104+1.35*'G-2'!F113+1.5*'Q-2'!F131 -> -111.15925 | E23: ='G-1'!G104+1.35*'G-2'!G113+1.5*'Q-2'!G131 -> 0 | F23: ='G-1'!H104+1.35*'G-2'!H113+1.5*'Q-2'!H131 -> 0 | G23: ='G-1'!I104+1.35*'G-2'!I113+1.5*'Q-2'!I131 -> 0 | H23: ='G-1'!J104+1.35*'G-2'!J113+1.5*'Q-2'!J131 -> 251.44873
A24: 5 | B24: 5 | C24: ='G-1'!E105+1.35*'G-2'!E114+1.5*'Q-2'!E132 -> 0 | D24: ='G-1'!F105+1.35*'G-2'!F114+1.5*'Q-2'!F132 -> -26.5951 | E24: ='G-1'!G105+1.35*'G-2'!G114+1.5*'Q-2'!G132 -> 0 | F24: ='G-1'!H105+1.35*'G-2'!H114+1.5*'Q-2'!H132 -> 0 | G24: ='G-1'!I105+1.35*'G-2'!I114+1.5*'Q-2'!I132 -> 0 | H24: ='G-1'!J105+1.35*'G-2'!J114+1.5*'Q-2'!J132 -> 320.7559
A25: 5 | B25: 6.25 | C25: ='G-1'!E106+1.35*'G-2'!E115+1.5*'Q-2'!E133 -> 0 | D25: ='G-1'!F106+1.35*'G-2'!F115+1.5*'Q-2'!F133 -> 57.9704 | E25: ='G-1'!G106+1.35*'G-2'!G115+1.5*'Q-2'!G133 -> 0 | F25: ='G-1'!H106+1.35*'G-2'!H115+1.5*'Q-2'!H133 -> 0 | G25: ='G-1'!I106+1.35*'G-2'!I115+1.5*'Q-2'!I133 -> 0 | H25: ='G-1'!J106+1.35*'G-2'!J115+1.5*'Q-2'!J133 -> 304.97023
A26: 5 | B26: 7.5 | C26: ='G-1'!E107+1.35*'G-2'!E116+1.5*'Q-2'!E134 -> 0 | D26: ='G-1'!F107+1.35*'G-2'!F116+1.5*'Q-2'!F134 -> 142.53455 | E26: ='G-1'!G107+1.35*'G-2'!G116+1.5*'Q-2'!G134 -> 0 | F26: ='G-1'!H107+1.35*'G-2'!H116+1.5*'Q-2'!H134 -> 0 | G26: ='G-1'!I107+1.35*'G-2'!I116+1.5*'Q-2'!I134 -> 0 | H26: ='G-1'!J107+1.35*'G-2'!J116+1.5*'Q-2'!J134 -> 204.09156
A27: 5 | B27: 8.75 | C27: ='G-1'!E108+1.35*'G-2'!E117+1.5*'Q-2'!E135 -> 0 | D27: ='G-1'!F108+1.35*'G-2'!F117+1.5*'Q-2'!F135 -> 227.0972 | E27: ='G-1'!G108+1.35*'G-2'!G117+1.5*'Q-2'!G135 -> 0 | F27: ='G-1'!H108+1.35*'G-2'!H117+1.5*'Q-2'!H135 -> 0 | G27: ='G-1'!I108+1.35*'G-2'!I117+1.5*'Q-2'!I135 -> 0 | H27: ='G-1'!J108+1.35*'G-2'!J117+1.5*'Q-2'!J135 -> 18.120405
A28: 5 | B28: 10 | C28: ='G-1'!E109+1.35*'G-2'!E118+1.5*'Q-2'!E136 -> 0 | D28: ='G-1'!F109+1.35*'G-2'!F118+1.5*'Q-2'!F136 -> 311.6627 | E28: ='G-1'!G109+1.35*'G-2'!G118+1.5*'Q-2'!G136 -> 0 | F28: ='G-1'!H109+1.35*'G-2'!H118+1.5*'Q-2'!H136 -> 0 | G28: ='G-1'!I109+1.35*'G-2'!I118+1.5*'Q-2'!I136 -> 0 | H28: ='G-1'!J109+1.35*'G-2'!J118+1.5*'Q-2'!J136 -> -252.94357

Sheet EQ+
A1: Frame | B1: Station | C1: P | D1: V2 | E1: V3 | F1: T | G1: M2 | H1: M3
A2: 1 | B2: 0 | C2: ='G-1'!E5+'G-2'!E8+0.3*('Q-1'!E11+'Q-2'!E14)+EX!E2 -> -145.4531 | D2: ='G-1'!F5+'G-2'!F8+0.3*('Q-1'!F11+'Q-2'!F14)+EX!F2 -> 3.2589 | E2: ='G-1'!G5+'G-2'!G8+0.3*('Q-1'!G11+'Q-2'!G14)+EX!G2 -> 0 | F2: ='G-1'!H5+'G-2'!H8+0.3*('Q-1'!H11+'Q-2'!H14)+EX!H2 -> 0 | G2: ='G-1'!I5+'G-2'!I8+0.3*('Q-1'!I11+'Q-2'!I14)+EX!I2 -> 0 | H2: ='G-1'!J5+'G-2'!J8+0.3*('Q-1'!J11+'Q-2'!J14)+EX!J2 -> 63.1337
A3: 1 | B3: 3.25 | C3: ='G-1'!E6+'G-2'!E9+0.3*('Q-1'!E12+'Q-2'!E15)+EX!E3 -> -145.4531 | D3: ='G-1'!F6+'G-2'!F9+0.3*('Q-1'!F12+'Q-2'!F15)+EX!F3 -> 3.2589 | E3: ='G-1'!G6+'G-2'!G9+0.3*('Q-1'!G12+'Q-2'!G15)+EX!G3 -> 0 | F3: ='G-1'!H6+'G-2'!H9+0.3*('Q-1'!H12+'Q-2'!H15)+EX!H3 -> 0 | G3: ='G-1'!I6+'G-2'!I9+0.3*('Q-1'!I12+'Q-2'!I15)+EX!I3 -> 0 | H3: ='G-1'!J6+'G-2'!J9+0.3*('Q-1'!J12+'Q-2'!J15)+EX!J3 -> 54.66074
A4: 1 | B4: 6.5 | C4: ='G-1'!E7+'G-2'!E10+0.3*('Q-1'!E13+'Q-2'!E16)+EX!E4 -> -145.4531 | D4: ='G-1'!F7+'G-2'!F10+0.3*('Q-1'!F13+'Q-2'!F16)+EX!F4 -> 3.2589 | E4: ='G-1'!G7+'G-2'!G10+0.3*('Q-1'!G13+'Q-2'!G16)+EX!G4 -> 0 | F4: ='G-1'!H7+'G-2'!H10+0.3*('Q-1'!H13+'Q-2'!H16)+EX!H4 -> 0 | G4: ='G-1'!I7+'G-2'!I10+0.3*('Q-1'!I13+'Q-2'!I16)+EX!I4 -> 0 | H4: ='G-1'!J7+'G-2'!J10+0.3*('Q-1'!J13+'Q-2'!J16)+EX!J4 -> 46.18758
A5: 2 | B5: 0 | C5: ='G-1'!E20+'G-2'!E23+0.3*('Q-1'!E26+'Q-2'!E29)+EX!E17 -> -411.1394 | D5: ='G-1'!F20+'G-2'!F23+0.3*('Q-1'!F26+'Q-2'!F29)+EX!F17 -> 52.992 | E5: ='G-1'!G20+'G-2'!G23+0.3*('Q-1'!G26+'Q-2'!G29)+EX!G17 -> 0 | F5: ='G-1'!H20+'G-2'!H23+0.3*('Q-1'!H26+'Q-2'!H29)+EX!H17 -> 0 | G5: ='G-1'!I20+'G-2'!I23+0.3*('Q-1'!I26+'Q-2'!I29)+EX!I17 -> 0 | H5: ='G-1'!J20+'G-2'!J23+0.3*('Q-1'!J26+'Q-2'!J29)+EX!J17 -> 146.3998
A6: 2 | B6: 3.25 | C6: ='G-1'!E21+'G-2'!E24+0.3*('Q-1'!E27+'Q-2'!E30)+EX!E18 -> -411.1394 | D6: ='G-1'!F21+'G-2'!F24+0.3*('Q-1'!F27+'Q-2'!F30)+EX!F18 -> 52.992 | E6: ='G-1'!G21+'G-2'!G24+0.3*('Q-1'!G27+'Q-2'!G30)+EX!G18 -> 0 | F6: ='G-1'!H21+'G-2'!H24+0.3*('Q-1'!H27+'Q-2'!H30)+EX!H18 -> 0 | G6: ='G-1'!I21+'G-2'!I24+0.3*('Q-1'!I27+'Q-2'!I30)+EX!I18 -> 0 | H6: ='G-1'!J21+'G-2'!J24+0.3*('Q-1'!J27+'Q-2'!J30)+EX!J18 -> 8.6205
A7: 2 | B7: 6.5 | C7: ='G-1'!E22+'G-2'!E25+0.3*('Q-1'!E28+'Q-2'!E31)+EX!E19 -> -411.1394 | D7: ='G-1'!F22+'G-2'!F25+0.3*('Q-1'!F28+'Q-2'!F31)+EX!F19 -> 52.992 | E7: ='G-1'!G22+'G-2'!G25+0.3*('Q-1'!G28+'Q-2'!G31)+EX!G19 -> 0 | F7: ='G-1'!H22+'G-2'!H25+0.3*('Q-1'!H28+'Q-2'!H31)+EX!H19 -> 0 | G7: ='G-1'!I22+'G-2'!I25+0.3*('Q-1'!I28+'Q-2'!I31)+EX!I19 -> 0 | H7: ='G-1'!J22+'G-2'!J25+0.3*('Q-1'!J28+'Q-2'!J31)+EX!J19 -> -129.1589
A8: 3 | B8: 0 | C8: ='G-1'!E35+'G-2'!E38+0.3*('Q-1'!E41+'Q-2'!E44)+EX!E32 -> -182.8411 | D8: ='G-1'!F35+'G-2'!F38+0.3*('Q-1'!F41+'Q-2'!F44)+EX!F32 -> 78.1891 | E8: ='G-1'!G35+'G-2'!G38+0.3*('Q-1'!G41+'Q-2'!G44)+EX!G32 -> 0 | F8: ='G-1'!H35+'G-2'!H38+0.3*('Q-1'!H41+'Q-2'!H44)+EX!H32 -> 0 | G8: ='G-1'!I35+'G-2'!I38+0.3*('Q-1'!I41+'Q-2'!I44)+EX!I32 -> 0 | H8: ='G-1'!J35+'G-2'!J38+0.3*('Q-1'!J41+'Q-2'!J44)+EX!J32 -> 188.5861
A9: 3 | B9: 3.25 | C9: ='G-1'!E36+'G-2'!E39+0.3*('Q-1'!E42+'Q-2'!E45)+EX!E33 -> -182.8411 | D9: ='G-1'!F36+'G-2'!F39+0.3*('Q-1'!F42+'Q-2'!F45)+EX!F33 -> 78.1891 | E9: ='G-1'!G36+'G-2'!G39+0.3*('Q-1'!G42+'Q-2'!G45)+EX!G33 -> 0 | F9: ='G-1'!H36+'G-2'!H39+0.3*('Q-1'!H42+'Q-2'!H45)+EX!H33 -> 0 | G9: ='G-1'!I36+'G-2'!I39+0.3*('Q-1'!I42+'Q-2'!I45)+EX!I33 -> 0 | H9: ='G-1'!J36+'G-2'!J39+0.3*('Q-1'!J42+'Q-2'!J45)+EX!J33 -> -14.70554
A10: 3 | B10: 6.5 | C10: ='G-1'!E37+'G-2'!E40+0.3*('Q-1'!E43+'Q-2'!E46)+EX!E34 -> -182.8411 | D10: ='G-1'!F37+'G-2'!F40+0.3*('Q-1'!F43+'Q-2'!F46)+EX!F34 -> 78.1891 | E10: ='G-1'!G37+'G-2'!G40+0.3*('Q-1'!G43+'Q-2'!G46)+EX!G34 -> 0 | F10: ='G-1'!H37+'G-2'!H40+0.3*('Q-1'!H43+'Q-2'!H46)+EX!H34 -> 0 | G10: ='G-1'!I37+'G-2'!I40+0.3*('Q-1'!I43+'Q-2'!I46)+EX!I34 -> 0 | H10: ='G-1'!J37+'G-2'!J40+0.3*('Q-1'!J43+'Q-2'!J46)+EX!J34 -> -217.99718
A11: 4 | B11: 0 | C11: ='G-1'!E56+'G-2'!E65+0.3*('Q-1'!E74+'Q-2'!E83)+EX!E47 -> 0 | D11: ='G-1'!F56+'G-2'!F65+0.3*('Q-1'!F74+'Q-2'!F83)+EX!F47 -> -145.4531 | E11: ='G-1'!G56+'G-2'!G65+0.3*('Q-1'!G74+'Q-2'!G83)+EX!G47 -> 0 | F11: ='G-1'!H56+'G-2'!H65+0.3*('Q-1'!H74+'Q-2'!H83)+EX!H47 -> 0 | G11: ='G-1'!I56+'G-2'!I65+0.3*('Q-1'!I74+'Q-2'!I83)+EX!I47 -> 0 | H11: ='G-1'!J56+'G-2'!J65+0.3*('Q-1'!J74+'Q-2'!J83)+EX!J47 -> -46.18758
A12: 4 | B12: 1.25 | C12: ='G-1'!E57+'G-2'!E66+0.3*('Q-1'!E75+'Q-2'!E84)+EX!E48 -> 0 | D12: ='G-1'!F57+'G-2'!F66+0.3*('Q-1'!F75+'Q-2'!F84)+EX!F48 -> -99.2378 | E12: ='G-1'!G57+'G-2'!G66+0.3*('Q-1'!G75+'Q-2'!G84)+EX!G48 -> 0 | F12: ='G-1'!H57+'G-2'!H66+0.3*('Q-1'!H75+'Q-2'!H84)+EX!H48 -> 0 | G12: ='G-1'!I57+'G-2'!I66+0.3*('Q-1'!I75+'Q-2'!I84)+EX!I48 -> 0 | H12: ='G-1'!J57+'G-2'!J66+0.3*('Q-1'!J75+'Q-2'!J84)+EX!J48 -> 76.92284
A13: 4 | B13: 2.5 | C13: ='G-1'!E58+'G-2'!E67+0.3*('Q-1'!E76+'Q-2'!E85)+EX!E49 -> 0 | D13: ='G-1'!F58+'G-2'!F67+0.3*('Q-1'!F76+'Q-2'!F85)+EX!F49 -> -53.0238 | E13: ='G-1'!G58+'G-2'!G67+0.3*('Q-1'!G76+'Q-2'!G85)+EX!G49 -> 0 | F13: ='G-1'!H58+'G-2'!H67+0.3*('Q-1'!H76+'Q-2'!H85)+EX!H49 -> 0 | G13: ='G-1'!I58+'G-2'!I67+0.3*('Q-1'!I76+'Q-2'!I85)+EX!I49 -> 0 | H13: ='G-1'!J58+'G-2'!J67+0.3*('Q-1'!J76+'Q-2'!J85)+EX!J49 -> 153.52987
A14: 4 | B14: 3.75 | C14: ='G-1'!E59+'G-2'!E68+0.3*('Q-1'!E77+'Q-2'!E86)+EX!E50 -> 0 | D14: ='G-1'!F59+'G-2'!F68+0.3*('Q-1'!F77+'Q-2'!F86)+EX!F50 -> -6.8095 | E14: ='G-1'!G59+'G-2'!G68+0.3*('Q-1'!G77+'Q-2'!G86)+EX!G50 -> 0 | F14: ='G-1'!H59+'G-2'!H68+0.3*('Q-1'!H77+'Q-2'!H86)+EX!H50 -> 0 | G14: ='G-1'!I59+'G-2'!I68+0.3*('Q-1'!I77+'Q-2'!I86)+EX!I50 -> 0 | H14: ='G-1'!J59+'G-2'!J68+0.3*('Q-1'!J77+'Q-2'!J86)+EX!J50 -> 183.63371
A15: 4 | B15: 5 | C15: ='G-1'!E60+'G-2'!E69+0.3*('Q-1'!E78+'Q-2'!E87)+EX!E51 -> 0 | D15: ='G-1'!F60+'G-2'!F69+0.3*('Q-1'!F78+'Q-2'!F87)+EX!F51 -> 39.4058 | E15: ='G-1'!G60+'G-2'!G69+0.3*('Q-1'!G78+'Q-2'!G87)+EX!G51 -> 0 | F15: ='G-1'!H60+'G-2'!H69+0.3*('Q-1'!H78+'Q-2'!H87)+EX!H51 -> 0 | G15: ='G-1'!I60+'G-2'!I69+0.3*('Q-1'!I78+'Q-2'!I87)+EX!I51 -> 0 | H15: ='G-1'!J60+'G-2'!J69+0.3*('Q-1'!J78+'Q-2'!J87)+EX!J51 -> 167.23393
A16: 4 | B16: 6.25 | C16: ='G-1'!E61+'G-2'!E70+0.3*('Q-1'!E79+'Q-2'!E88)+EX!E52 -> 0 | D16: ='G-1'!F61+'G-2'!F70+0.3*('Q-1'!F79+'Q-2'!F88)+EX!F52 -> 85.6201 | E16: ='G-1'!G61+'G-2'!G70+0.3*('Q-1'!G79+'Q-2'!G88)+EX!G52 -> 0 | F16: ='G-1'!H61+'G-2'!H70+0.3*('Q-1'!H79+'Q-2'!H88)+EX!H52 -> 0 | G16: ='G-1'!I61+'G-2'!I70+0.3*('Q-1'!I79+'Q-2'!I88)+EX!I52 -> 0 | H16: ='G-1'!J61+'G-2'!J70+0.3*('Q-1'!J79+'Q-2'!J88)+EX!J52 -> 104.33083
A17: 4 | B17: 7.5 | C17: ='G-1'!E62+'G-2'!E71+0.3*('Q-1'!E80+'Q-2'!E89)+EX!E53 -> 0 | D17: ='G-1'!F62+'G-2'!F71+0.3*('Q-1'!F80+'Q-2'!F89)+EX!F53 -> 131.8341 | E17: ='G-1'!G62+'G-2'!G71+0.3*('Q-1'!G80+'Q-2'!G89)+EX!G53 -> 0 | F17: ='G-1'!H62+'G-2'!H71+0.3*('Q-1'!H80+'Q-2'!H89)+EX!H53 -> 0 | G17: ='G-1'!I62+'G-2'!I71+0.3*('Q-1'!I80+'Q-2'!I89)+EX!I53 -> 0 | H17: ='G-1'!J62+'G-2'!J71+0.3*('Q-1'!J80+'Q-2'!J89)+EX!J53 -> -5.07553
A18: 4 | B18: 8.75 | C18: ='G-1'!E63+'G-2'!E72+0.3*('Q-1'!E81+'Q-2'!E90)+EX!E54 -> 0 | D18: ='G-1'!F63+'G-2'!F72+0.3*('Q-1'!F81+'Q-2'!F90)+EX!F54 -> 178.0484 | E18: ='G-1'!G63+'G-2'!G72+0.3*('Q-1'!G81+'Q-2'!G90)+EX!G54 -> 0 | F18: ='G-1'!H63+'G-2'!H72+0.3*('Q-1'!H81+'Q-2'!H90)+EX!H54 -> 0 | G18: ='G-1'!I63+'G-2'!I72+0.3*('Q-1'!I81+'Q-2'!I90)+EX!I54 -> 0 | H18: ='G-1'!J63+'G-2'!J72+0.3*('Q-1'!J81+'Q-2'!J90)+EX!J54 -> -160.98544
A19: 4 | B19: 10 | C19: ='G-1'!E64+'G-2'!E73+0.3*('Q-1'!E82+'Q-2'!E91)+EX!E55 -> 0 | D19: ='G-1'!F64+'G-2'!F73+0.3*('Q-1'!F82+'Q-2'!F91)+EX!F55 -> 224.2637 | E19: ='G-1'!G64+'G-2'!G73+0.3*('Q-1'!G82+'Q-2'!G91)+EX!G55 -> 0 | F19: ='G-1'!H64+'G-2'!H73+0.3*('Q-1'!H82+'Q-2'!H91)+EX!H55 -> 0 | G19: ='G-1'!I64+'G-2'!I73+0.3*('Q-1'!I82+'Q-2'!I91)+EX!I55 -> 0 | H19: ='G-1'!J64+'G-2'!J73+0.3*('Q-1'!J82+'Q-2'!J91)+EX!J55 -> -363.39864
